Traceback (most recent call last):
  File "/scratch/project_2000339/boeiradi/anaconda3/lib/python3.7/site-packages/xarray/backends/file_manager.py", line 199, in _acquire_with_cache_info
    file = self._cache[self._key]
  File "/scratch/project_2000339/boeiradi/anaconda3/lib/python3.7/site-packages/xarray/backends/lru_cache.py", line 53, in __getitem__
    value = self._cache[key]
KeyError: [<class 'netCDF4._netCDF4.Dataset'>, ('/scratch/project_2000339/boeiradi/waom4_frc/waom4extend_grd.nc',), 'r', (('clobber', True), ('diskless', False), ('format', 'NETCDF4'), ('persist', False))]

During handling of the above exception, another exception occurred:

Traceback (most recent call last):
  File "/users/boeiradi/COLD_project/postprocessing/waom_notebook/Grid_avg_evolution/WAOM10x4x2extend_shflim_S_0.25Q_OHC+OSC+MKE_evolution_shelf.py", line 36, in <module>
    dg4 = xr.open_dataset("/scratch/project_2000339/boeiradi/waom4_frc/waom4extend_grd.nc")
  File "/scratch/project_2000339/boeiradi/anaconda3/lib/python3.7/site-packages/xarray/backends/api.py", line 499, in open_dataset
    **kwargs,
  File "/scratch/project_2000339/boeiradi/anaconda3/lib/python3.7/site-packages/xarray/backends/netCDF4_.py", line 559, in open_dataset
    autoclose=autoclose,
  File "/scratch/project_2000339/boeiradi/anaconda3/lib/python3.7/site-packages/xarray/backends/netCDF4_.py", line 379, in open
    return cls(manager, group=group, mode=mode, lock=lock, autoclose=autoclose)
  File "/scratch/project_2000339/boeiradi/anaconda3/lib/python3.7/site-packages/xarray/backends/netCDF4_.py", line 327, in __init__
    self.format = self.ds.data_model
  File "/scratch/project_2000339/boeiradi/anaconda3/lib/python3.7/site-packages/xarray/backends/netCDF4_.py", line 388, in ds
    return self._acquire()
  File "/scratch/project_2000339/boeiradi/anaconda3/lib/python3.7/site-packages/xarray/backends/netCDF4_.py", line 382, in _acquire
    with self._manager.acquire_context(needs_lock) as root:
  File "/scratch/project_2000339/boeiradi/anaconda3/lib/python3.7/contextlib.py", line 112, in __enter__
    return next(self.gen)
  File "/scratch/project_2000339/boeiradi/anaconda3/lib/python3.7/site-packages/xarray/backends/file_manager.py", line 187, in acquire_context
    file, cached = self._acquire_with_cache_info(needs_lock)
  File "/scratch/project_2000339/boeiradi/anaconda3/lib/python3.7/site-packages/xarray/backends/file_manager.py", line 205, in _acquire_with_cache_info
    file = self._opener(*self._args, **kwargs)
  File "netCDF4/_netCDF4.pyx", line 2321, in netCDF4._netCDF4.Dataset.__init__
  File "netCDF4/_netCDF4.pyx", line 1885, in netCDF4._netCDF4._ensure_nc_success
FileNotFoundError: [Errno 2] No such file or directory: b'/scratch/project_2000339/boeiradi/waom4_frc/waom4extend_grd.nc'
srun: error: r14c45: task 0: Exited with exit code 1
srun: launch/slurm: _step_signal: Terminating StepId=10156241.0
