/CSC_CONTAINER/miniconda/envs/env1/lib/python3.8/site-packages/cartopy/mpl/geoaxes.py:1797: UserWarning: The input coordinates to pcolormesh are interpreted as cell centers, but are not monotonically increasing or decreasing. This may lead to incorrectly calculated cell edges, in which case, please supply explicit cell edges to pcolormesh.
  result = matplotlib.axes.Axes.pcolormesh(self, *args, **kwargs)
/CSC_CONTAINER/miniconda/envs/env1/lib/python3.8/site-packages/cartopy/mpl/geoaxes.py:1797: UserWarning: The input coordinates to pcolormesh are interpreted as cell centers, but are not monotonically increasing or decreasing. This may lead to incorrectly calculated cell edges, in which case, please supply explicit cell edges to pcolormesh.
  result = matplotlib.axes.Axes.pcolormesh(self, *args, **kwargs)
/CSC_CONTAINER/miniconda/envs/env1/lib/python3.8/site-packages/cartopy/mpl/geoaxes.py:1797: UserWarning: The input coordinates to pcolormesh are interpreted as cell centers, but are not monotonically increasing or decreasing. This may lead to incorrectly calculated cell edges, in which case, please supply explicit cell edges to pcolormesh.
  result = matplotlib.axes.Axes.pcolormesh(self, *args, **kwargs)
/CSC_CONTAINER/miniconda/envs/env1/lib/python3.8/site-packages/cartopy/mpl/geoaxes.py:1797: UserWarning: The input coordinates to pcolormesh are interpreted as cell centers, but are not monotonically increasing or decreasing. This may lead to incorrectly calculated cell edges, in which case, please supply explicit cell edges to pcolormesh.
  result = matplotlib.axes.Axes.pcolormesh(self, *args, **kwargs)
/CSC_CONTAINER/miniconda/envs/env1/lib/python3.8/site-packages/cartopy/mpl/geoaxes.py:1797: UserWarning: The input coordinates to pcolormesh are interpreted as cell centers, but are not monotonically increasing or decreasing. This may lead to incorrectly calculated cell edges, in which case, please supply explicit cell edges to pcolormesh.
  result = matplotlib.axes.Axes.pcolormesh(self, *args, **kwargs)
Traceback (most recent call last):
  File "/CSC_CONTAINER/miniconda/envs/env1/lib/python3.8/site-packages/xarray/backends/file_manager.py", line 201, in _acquire_with_cache_info
    file = self._cache[self._key]
  File "/CSC_CONTAINER/miniconda/envs/env1/lib/python3.8/site-packages/xarray/backends/lru_cache.py", line 55, in __getitem__
    value = self._cache[key]
KeyError: [<class 'netCDF4._netCDF4.Dataset'>, ('/scratch/project_2000789/boeiradi/waom4extend_shflim_S_0.25Q/output_01-10yr/ocean_avg_0001.nc',), 'r', (('clobber', True), ('diskless', False), ('format', 'NETCDF4'), ('persist', False))]

During handling of the above exception, another exception occurred:

Traceback (most recent call last):
  File "/users/boeiradi/COLD_project/postprocessing/waom_notebook/Grid_avg_evolution/WAOM4extend_shflim_S_0.25Q_SSS+OSC_evolution_shelf.py", line 311, in <module>
    read_roms_ts_4km(path_ECCO2_4km)
  File "/users/boeiradi/COLD_project/postprocessing/waom_notebook/Grid_avg_evolution/WAOM4extend_shflim_S_0.25Q_SSS+OSC_evolution_shelf.py", line 142, in read_roms_ts_4km
    ds = xr.open_dataset(exp_path + 'ocean_avg_00' + yr + '.nc')
  File "/CSC_CONTAINER/miniconda/envs/env1/lib/python3.8/site-packages/xarray/backends/api.py", line 531, in open_dataset
    backend_ds = backend.open_dataset(
  File "/CSC_CONTAINER/miniconda/envs/env1/lib/python3.8/site-packages/xarray/backends/netCDF4_.py", line 555, in open_dataset
    store = NetCDF4DataStore.open(
  File "/CSC_CONTAINER/miniconda/envs/env1/lib/python3.8/site-packages/xarray/backends/netCDF4_.py", line 384, in open
    return cls(manager, group=group, mode=mode, lock=lock, autoclose=autoclose)
  File "/CSC_CONTAINER/miniconda/envs/env1/lib/python3.8/site-packages/xarray/backends/netCDF4_.py", line 332, in __init__
    self.format = self.ds.data_model
  File "/CSC_CONTAINER/miniconda/envs/env1/lib/python3.8/site-packages/xarray/backends/netCDF4_.py", line 393, in ds
    return self._acquire()
  File "/CSC_CONTAINER/miniconda/envs/env1/lib/python3.8/site-packages/xarray/backends/netCDF4_.py", line 387, in _acquire
    with self._manager.acquire_context(needs_lock) as root:
  File "/CSC_CONTAINER/miniconda/envs/env1/lib/python3.8/contextlib.py", line 113, in __enter__
    return next(self.gen)
  File "/CSC_CONTAINER/miniconda/envs/env1/lib/python3.8/site-packages/xarray/backends/file_manager.py", line 189, in acquire_context
    file, cached = self._acquire_with_cache_info(needs_lock)
  File "/CSC_CONTAINER/miniconda/envs/env1/lib/python3.8/site-packages/xarray/backends/file_manager.py", line 207, in _acquire_with_cache_info
    file = self._opener(*self._args, **kwargs)
  File "src/netCDF4/_netCDF4.pyx", line 2353, in netCDF4._netCDF4.Dataset.__init__
  File "src/netCDF4/_netCDF4.pyx", line 1963, in netCDF4._netCDF4._ensure_nc_success
FileNotFoundError: [Errno 2] No such file or directory: b'/scratch/project_2000789/boeiradi/waom4extend_shflim_S_0.25Q/output_01-10yr/ocean_avg_0001.nc'
srun: error: r14c48: task 0: Exited with exit code 1
srun: launch/slurm: _step_signal: Terminating StepId=13651179.0
