/g/data3/hh5/public/apps/miniconda3/envs/analysis3-23.01/lib/python3.9/site-packages/distributed/node.py:182: UserWarning: Port 8787 is already in use.
Perhaps you already have a cluster running?
Hosting the HTTP server on port 39035 instead
  warnings.warn(
/g/data3/hh5/public/apps/miniconda3/envs/analysis3-23.01/lib/python3.9/site-packages/distributed/node.py:182: UserWarning: Port 8787 is already in use.
Perhaps you already have a cluster running?
Hosting the HTTP server on port 44897 instead
  warnings.warn(
/g/data3/hh5/public/apps/miniconda3/envs/analysis3-23.01/lib/python3.9/site-packages/distributed/node.py:182: UserWarning: Port 8787 is already in use.
Perhaps you already have a cluster running?
Hosting the HTTP server on port 46821 instead
  warnings.warn(
/g/data3/hh5/public/apps/miniconda3/envs/analysis3-23.01/lib/python3.9/site-packages/distributed/node.py:182: UserWarning: Port 8787 is already in use.
Perhaps you already have a cluster running?
Hosting the HTTP server on port 35681 instead
  warnings.warn(
/g/data3/hh5/public/apps/miniconda3/envs/analysis3-23.01/lib/python3.9/site-packages/distributed/node.py:182: UserWarning: Port 8787 is already in use.
Perhaps you already have a cluster running?
Hosting the HTTP server on port 32909 instead
  warnings.warn(
/g/data3/hh5/public/apps/miniconda3/envs/analysis3-23.01/lib/python3.9/site-packages/distributed/node.py:182: UserWarning: Port 8787 is already in use.
Perhaps you already have a cluster running?
Hosting the HTTP server on port 36525 instead
  warnings.warn(
/g/data3/hh5/public/apps/miniconda3/envs/analysis3-23.01/lib/python3.9/site-packages/distributed/node.py:182: UserWarning: Port 8787 is already in use.
Perhaps you already have a cluster running?
Hosting the HTTP server on port 37021 instead
  warnings.warn(
/g/data3/hh5/public/apps/miniconda3/envs/analysis3-23.01/lib/python3.9/site-packages/distributed/node.py:182: UserWarning: Port 8787 is already in use.
Perhaps you already have a cluster running?
Hosting the HTTP server on port 42011 instead
  warnings.warn(
2023-04-13 17:46:14,362 - distributed.nanny - ERROR - Failed to start process
Traceback (most recent call last):
  File "/g/data3/hh5/public/apps/miniconda3/envs/analysis3-23.01/lib/python3.9/site-packages/distributed/nanny.py", line 442, in instantiate
    result = await self.process.start()
  File "/g/data3/hh5/public/apps/miniconda3/envs/analysis3-23.01/lib/python3.9/site-packages/distributed/nanny.py", line 711, in start
    await self.process.start()
  File "/g/data3/hh5/public/apps/miniconda3/envs/analysis3-23.01/lib/python3.9/site-packages/distributed/process.py", line 55, in _call_and_set_future
    res = func(*args, **kwargs)
  File "/g/data3/hh5/public/apps/miniconda3/envs/analysis3-23.01/lib/python3.9/site-packages/distributed/process.py", line 215, in _start
    process.start()
  File "/g/data3/hh5/public/apps/miniconda3/envs/analysis3-23.01/lib/python3.9/multiprocessing/process.py", line 121, in start
    self._popen = self._Popen(self)
  File "/g/data3/hh5/public/apps/miniconda3/envs/analysis3-23.01/lib/python3.9/multiprocessing/context.py", line 284, in _Popen
    return Popen(process_obj)
  File "/g/data3/hh5/public/apps/miniconda3/envs/analysis3-23.01/lib/python3.9/multiprocessing/popen_spawn_posix.py", line 32, in __init__
    super().__init__(process_obj)
  File "/g/data3/hh5/public/apps/miniconda3/envs/analysis3-23.01/lib/python3.9/multiprocessing/popen_fork.py", line 19, in __init__
    self._launch(process_obj)
  File "/g/data3/hh5/public/apps/miniconda3/envs/analysis3-23.01/lib/python3.9/multiprocessing/popen_spawn_posix.py", line 42, in _launch
    prep_data = spawn.get_preparation_data(process_obj._name)
  File "/g/data3/hh5/public/apps/miniconda3/envs/analysis3-23.01/lib/python3.9/multiprocessing/spawn.py", line 154, in get_preparation_data
    _check_not_importing_main()
  File "/g/data3/hh5/public/apps/miniconda3/envs/analysis3-23.01/lib/python3.9/multiprocessing/spawn.py", line 134, in _check_not_importing_main
    raise RuntimeError('''
RuntimeError: 
        An attempt has been made to start a new process before the
        current process has finished its bootstrapping phase.

        This probably means that you are not using fork to start your
        child processes and you have forgotten to use the proper idiom
        in the main module:

            if __name__ == '__main__':
                freeze_support()
                ...

        The "freeze_support()" line can be omitted if the program
        is not going to be frozen to produce an executable.
2023-04-13 17:46:14,361 - distributed.nanny - ERROR - Failed to start process
Traceback (most recent call last):
  File "/g/data3/hh5/public/apps/miniconda3/envs/analysis3-23.01/lib/python3.9/site-packages/distributed/nanny.py", line 442, in instantiate
    result = await self.process.start()
  File "/g/data3/hh5/public/apps/miniconda3/envs/analysis3-23.01/lib/python3.9/site-packages/distributed/nanny.py", line 711, in start
    await self.process.start()
  File "/g/data3/hh5/public/apps/miniconda3/envs/analysis3-23.01/lib/python3.9/site-packages/distributed/process.py", line 55, in _call_and_set_future
    res = func(*args, **kwargs)
  File "/g/data3/hh5/public/apps/miniconda3/envs/analysis3-23.01/lib/python3.9/site-packages/distributed/process.py", line 215, in _start
    process.start()
  File "/g/data3/hh5/public/apps/miniconda3/envs/analysis3-23.01/lib/python3.9/multiprocessing/process.py", line 121, in start
    self._popen = self._Popen(self)
  File "/g/data3/hh5/public/apps/miniconda3/envs/analysis3-23.01/lib/python3.9/multiprocessing/context.py", line 284, in _Popen
    return Popen(process_obj)
  File "/g/data3/hh5/public/apps/miniconda3/envs/analysis3-23.01/lib/python3.9/multiprocessing/popen_spawn_posix.py", line 32, in __init__
    super().__init__(process_obj)
  File "/g/data3/hh5/public/apps/miniconda3/envs/analysis3-23.01/lib/python3.9/multiprocessing/popen_fork.py", line 19, in __init__
    self._launch(process_obj)
  File "/g/data3/hh5/public/apps/miniconda3/envs/analysis3-23.01/lib/python3.9/multiprocessing/popen_spawn_posix.py", line 42, in _launch
    prep_data = spawn.get_preparation_data(process_obj._name)
  File "/g/data3/hh5/public/apps/miniconda3/envs/analysis3-23.01/lib/python3.9/multiprocessing/spawn.py", line 154, in get_preparation_data
    _check_not_importing_main()
  File "/g/data3/hh5/public/apps/miniconda3/envs/analysis3-23.01/lib/python3.9/multiprocessing/spawn.py", line 134, in _check_not_importing_main
    raise RuntimeError('''
RuntimeError: 
        An attempt has been made to start a new process before the
        current process has finished its bootstrapping phase.

        This probably means that you are not using fork to start your
        child processes and you have forgotten to use the proper idiom
        in the main module:

            if __name__ == '__main__':
                freeze_support()
                ...

        The "freeze_support()" line can be omitted if the program
        is not going to be frozen to produce an executable.
2023-04-13 17:46:14,355 - distributed.nanny - ERROR - Failed to start process
Traceback (most recent call last):
  File "/g/data3/hh5/public/apps/miniconda3/envs/analysis3-23.01/lib/python3.9/site-packages/distributed/nanny.py", line 442, in instantiate
    result = await self.process.start()
  File "/g/data3/hh5/public/apps/miniconda3/envs/analysis3-23.01/lib/python3.9/site-packages/distributed/nanny.py", line 711, in start
    await self.process.start()
  File "/g/data3/hh5/public/apps/miniconda3/envs/analysis3-23.01/lib/python3.9/site-packages/distributed/process.py", line 55, in _call_and_set_future
    res = func(*args, **kwargs)
  File "/g/data3/hh5/public/apps/miniconda3/envs/analysis3-23.01/lib/python3.9/site-packages/distributed/process.py", line 215, in _start
    process.start()
  File "/g/data3/hh5/public/apps/miniconda3/envs/analysis3-23.01/lib/python3.9/multiprocessing/process.py", line 121, in start
    self._popen = self._Popen(self)
  File "/g/data3/hh5/public/apps/miniconda3/envs/analysis3-23.01/lib/python3.9/multiprocessing/context.py", line 284, in _Popen
    return Popen(process_obj)
  File "/g/data3/hh5/public/apps/miniconda3/envs/analysis3-23.01/lib/python3.9/multiprocessing/popen_spawn_posix.py", line 32, in __init__
    super().__init__(process_obj)
  File "/g/data3/hh5/public/apps/miniconda3/envs/analysis3-23.01/lib/python3.9/multiprocessing/popen_fork.py", line 19, in __init__
    self._launch(process_obj)
  File "/g/data3/hh5/public/apps/miniconda3/envs/analysis3-23.01/lib/python3.9/multiprocessing/popen_spawn_posix.py", line 42, in _launch
    prep_data = spawn.get_preparation_data(process_obj._name)
  File "/g/data3/hh5/public/apps/miniconda3/envs/analysis3-23.01/lib/python3.9/multiprocessing/spawn.py", line 154, in get_preparation_data
    _check_not_importing_main()
  File "/g/data3/hh5/public/apps/miniconda3/envs/analysis3-23.01/lib/python3.9/multiprocessing/spawn.py", line 134, in _check_not_importing_main
    raise RuntimeError('''
RuntimeError: 
        An attempt has been made to start a new process before the
        current process has finished its bootstrapping phase.

        This probably means that you are not using fork to start your
        child processes and you have forgotten to use the proper idiom
        in the main module:

            if __name__ == '__main__':
                freeze_support()
                ...

        The "freeze_support()" line can be omitted if the program
        is not going to be frozen to produce an executable.
2023-04-13 17:46:14,374 - distributed.nanny - ERROR - Failed to start process
Traceback (most recent call last):
  File "/g/data3/hh5/public/apps/miniconda3/envs/analysis3-23.01/lib/python3.9/site-packages/distributed/nanny.py", line 442, in instantiate
    result = await self.process.start()
  File "/g/data3/hh5/public/apps/miniconda3/envs/analysis3-23.01/lib/python3.9/site-packages/distributed/nanny.py", line 711, in start
    await self.process.start()
  File "/g/data3/hh5/public/apps/miniconda3/envs/analysis3-23.01/lib/python3.9/site-packages/distributed/process.py", line 55, in _call_and_set_future
    res = func(*args, **kwargs)
  File "/g/data3/hh5/public/apps/miniconda3/envs/analysis3-23.01/lib/python3.9/site-packages/distributed/process.py", line 215, in _start
    process.start()
  File "/g/data3/hh5/public/apps/miniconda3/envs/analysis3-23.01/lib/python3.9/multiprocessing/process.py", line 121, in start
    self._popen = self._Popen(self)
  File "/g/data3/hh5/public/apps/miniconda3/envs/analysis3-23.01/lib/python3.9/multiprocessing/context.py", line 284, in _Popen
    return Popen(process_obj)
  File "/g/data3/hh5/public/apps/miniconda3/envs/analysis3-23.01/lib/python3.9/multiprocessing/popen_spawn_posix.py", line 32, in __init__
    super().__init__(process_obj)
  File "/g/data3/hh5/public/apps/miniconda3/envs/analysis3-23.01/lib/python3.9/multiprocessing/popen_fork.py", line 19, in __init__
    self._launch(process_obj)
  File "/g/data3/hh5/public/apps/miniconda3/envs/analysis3-23.01/lib/python3.9/multiprocessing/popen_spawn_posix.py", line 42, in _launch
    prep_data = spawn.get_preparation_data(process_obj._name)
  File "/g/data3/hh5/public/apps/miniconda3/envs/analysis3-23.01/lib/python3.9/multiprocessing/spawn.py", line 154, in get_preparation_data
    _check_not_importing_main()
  File "/g/data3/hh5/public/apps/miniconda3/envs/analysis3-23.01/lib/python3.9/multiprocessing/spawn.py", line 134, in _check_not_importing_main
    raise RuntimeError('''
RuntimeError: 
        An attempt has been made to start a new process before the
        current process has finished its bootstrapping phase.

        This probably means that you are not using fork to start your
        child processes and you have forgotten to use the proper idiom
        in the main module:

            if __name__ == '__main__':
                freeze_support()
                ...

        The "freeze_support()" line can be omitted if the program
        is not going to be frozen to produce an executable.
2023-04-13 17:46:14,353 - distributed.nanny - ERROR - Failed to start process
Traceback (most recent call last):
  File "/g/data3/hh5/public/apps/miniconda3/envs/analysis3-23.01/lib/python3.9/site-packages/distributed/nanny.py", line 442, in instantiate
    result = await self.process.start()
  File "/g/data3/hh5/public/apps/miniconda3/envs/analysis3-23.01/lib/python3.9/site-packages/distributed/nanny.py", line 711, in start
    await self.process.start()
  File "/g/data3/hh5/public/apps/miniconda3/envs/analysis3-23.01/lib/python3.9/site-packages/distributed/process.py", line 55, in _call_and_set_future
    res = func(*args, **kwargs)
  File "/g/data3/hh5/public/apps/miniconda3/envs/analysis3-23.01/lib/python3.9/site-packages/distributed/process.py", line 215, in _start
    process.start()
  File "/g/data3/hh5/public/apps/miniconda3/envs/analysis3-23.01/lib/python3.9/multiprocessing/process.py", line 121, in start
    self._popen = self._Popen(self)
  File "/g/data3/hh5/public/apps/miniconda3/envs/analysis3-23.01/lib/python3.9/multiprocessing/context.py", line 284, in _Popen
    return Popen(process_obj)
  File "/g/data3/hh5/public/apps/miniconda3/envs/analysis3-23.01/lib/python3.9/multiprocessing/popen_spawn_posix.py", line 32, in __init__
    super().__init__(process_obj)
  File "/g/data3/hh5/public/apps/miniconda3/envs/analysis3-23.01/lib/python3.9/multiprocessing/popen_fork.py", line 19, in __init__
    self._launch(process_obj)
  File "/g/data3/hh5/public/apps/miniconda3/envs/analysis3-23.01/lib/python3.9/multiprocessing/popen_spawn_posix.py", line 42, in _launch
    prep_data = spawn.get_preparation_data(process_obj._name)
  File "/g/data3/hh5/public/apps/miniconda3/envs/analysis3-23.01/lib/python3.9/multiprocessing/spawn.py", line 154, in get_preparation_data
    _check_not_importing_main()
  File "/g/data3/hh5/public/apps/miniconda3/envs/analysis3-23.01/lib/python3.9/multiprocessing/spawn.py", line 134, in _check_not_importing_main
    raise RuntimeError('''
RuntimeError: 
        An attempt has been made to start a new process before the
        current process has finished its bootstrapping phase.

        This probably means that you are not using fork to start your
        child processes and you have forgotten to use the proper idiom
        in the main module:

            if __name__ == '__main__':
                freeze_support()
                ...

        The "freeze_support()" line can be omitted if the program
        is not going to be frozen to produce an executable.
2023-04-13 17:46:14,354 - distributed.nanny - ERROR - Failed to start process
Traceback (most recent call last):
  File "/g/data3/hh5/public/apps/miniconda3/envs/analysis3-23.01/lib/python3.9/site-packages/distributed/nanny.py", line 442, in instantiate
    result = await self.process.start()
  File "/g/data3/hh5/public/apps/miniconda3/envs/analysis3-23.01/lib/python3.9/site-packages/distributed/nanny.py", line 711, in start
    await self.process.start()
  File "/g/data3/hh5/public/apps/miniconda3/envs/analysis3-23.01/lib/python3.9/site-packages/distributed/process.py", line 55, in _call_and_set_future
    res = func(*args, **kwargs)
  File "/g/data3/hh5/public/apps/miniconda3/envs/analysis3-23.01/lib/python3.9/site-packages/distributed/process.py", line 215, in _start
    process.start()
  File "/g/data3/hh5/public/apps/miniconda3/envs/analysis3-23.01/lib/python3.9/multiprocessing/process.py", line 121, in start
    self._popen = self._Popen(self)
  File "/g/data3/hh5/public/apps/miniconda3/envs/analysis3-23.01/lib/python3.9/multiprocessing/context.py", line 284, in _Popen
    return Popen(process_obj)
  File "/g/data3/hh5/public/apps/miniconda3/envs/analysis3-23.01/lib/python3.9/multiprocessing/popen_spawn_posix.py", line 32, in __init__
    super().__init__(process_obj)
  File "/g/data3/hh5/public/apps/miniconda3/envs/analysis3-23.01/lib/python3.9/multiprocessing/popen_fork.py", line 19, in __init__
    self._launch(process_obj)
  File "/g/data3/hh5/public/apps/miniconda3/envs/analysis3-23.01/lib/python3.9/multiprocessing/popen_spawn_posix.py", line 42, in _launch
    prep_data = spawn.get_preparation_data(process_obj._name)
  File "/g/data3/hh5/public/apps/miniconda3/envs/analysis3-23.01/lib/python3.9/multiprocessing/spawn.py", line 154, in get_preparation_data
    _check_not_importing_main()
  File "/g/data3/hh5/public/apps/miniconda3/envs/analysis3-23.01/lib/python3.9/multiprocessing/spawn.py", line 134, in _check_not_importing_main
    raise RuntimeError('''
RuntimeError: 
        An attempt has been made to start a new process before the
        current process has finished its bootstrapping phase.

        This probably means that you are not using fork to start your
        child processes and you have forgotten to use the proper idiom
        in the main module:

            if __name__ == '__main__':
                freeze_support()
                ...

        The "freeze_support()" line can be omitted if the program
        is not going to be frozen to produce an executable.
2023-04-13 17:46:14,419 - distributed.nanny - ERROR - Failed to start process
Traceback (most recent call last):
  File "/g/data3/hh5/public/apps/miniconda3/envs/analysis3-23.01/lib/python3.9/site-packages/distributed/nanny.py", line 442, in instantiate
    result = await self.process.start()
  File "/g/data3/hh5/public/apps/miniconda3/envs/analysis3-23.01/lib/python3.9/site-packages/distributed/nanny.py", line 711, in start
    await self.process.start()
  File "/g/data3/hh5/public/apps/miniconda3/envs/analysis3-23.01/lib/python3.9/site-packages/distributed/process.py", line 55, in _call_and_set_future
    res = func(*args, **kwargs)
  File "/g/data3/hh5/public/apps/miniconda3/envs/analysis3-23.01/lib/python3.9/site-packages/distributed/process.py", line 215, in _start
    process.start()
  File "/g/data3/hh5/public/apps/miniconda3/envs/analysis3-23.01/lib/python3.9/multiprocessing/process.py", line 121, in start
    self._popen = self._Popen(self)
  File "/g/data3/hh5/public/apps/miniconda3/envs/analysis3-23.01/lib/python3.9/multiprocessing/context.py", line 284, in _Popen
    return Popen(process_obj)
  File "/g/data3/hh5/public/apps/miniconda3/envs/analysis3-23.01/lib/python3.9/multiprocessing/popen_spawn_posix.py", line 32, in __init__
    super().__init__(process_obj)
  File "/g/data3/hh5/public/apps/miniconda3/envs/analysis3-23.01/lib/python3.9/multiprocessing/popen_fork.py", line 19, in __init__
    self._launch(process_obj)
  File "/g/data3/hh5/public/apps/miniconda3/envs/analysis3-23.01/lib/python3.9/multiprocessing/popen_spawn_posix.py", line 42, in _launch
    prep_data = spawn.get_preparation_data(process_obj._name)
  File "/g/data3/hh5/public/apps/miniconda3/envs/analysis3-23.01/lib/python3.9/multiprocessing/spawn.py", line 154, in get_preparation_data
    _check_not_importing_main()
  File "/g/data3/hh5/public/apps/miniconda3/envs/analysis3-23.01/lib/python3.9/multiprocessing/spawn.py", line 134, in _check_not_importing_main
    raise RuntimeError('''
RuntimeError: 
        An attempt has been made to start a new process before the
        current process has finished its bootstrapping phase.

        This probably means that you are not using fork to start your
        child processes and you have forgotten to use the proper idiom
        in the main module:

            if __name__ == '__main__':
                freeze_support()
                ...

        The "freeze_support()" line can be omitted if the program
        is not going to be frozen to produce an executable.
2023-04-13 17:46:14,419 - distributed.nanny - ERROR - Failed to start process
Traceback (most recent call last):
  File "/g/data3/hh5/public/apps/miniconda3/envs/analysis3-23.01/lib/python3.9/site-packages/distributed/nanny.py", line 442, in instantiate
    result = await self.process.start()
  File "/g/data3/hh5/public/apps/miniconda3/envs/analysis3-23.01/lib/python3.9/site-packages/distributed/nanny.py", line 711, in start
    await self.process.start()
  File "/g/data3/hh5/public/apps/miniconda3/envs/analysis3-23.01/lib/python3.9/site-packages/distributed/process.py", line 55, in _call_and_set_future
    res = func(*args, **kwargs)
  File "/g/data3/hh5/public/apps/miniconda3/envs/analysis3-23.01/lib/python3.9/site-packages/distributed/process.py", line 215, in _start
    process.start()
  File "/g/data3/hh5/public/apps/miniconda3/envs/analysis3-23.01/lib/python3.9/multiprocessing/process.py", line 121, in start
    self._popen = self._Popen(self)
  File "/g/data3/hh5/public/apps/miniconda3/envs/analysis3-23.01/lib/python3.9/multiprocessing/context.py", line 284, in _Popen
    return Popen(process_obj)
  File "/g/data3/hh5/public/apps/miniconda3/envs/analysis3-23.01/lib/python3.9/multiprocessing/popen_spawn_posix.py", line 32, in __init__
    super().__init__(process_obj)
  File "/g/data3/hh5/public/apps/miniconda3/envs/analysis3-23.01/lib/python3.9/multiprocessing/popen_fork.py", line 19, in __init__
    self._launch(process_obj)
  File "/g/data3/hh5/public/apps/miniconda3/envs/analysis3-23.01/lib/python3.9/multiprocessing/popen_spawn_posix.py", line 42, in _launch
    prep_data = spawn.get_preparation_data(process_obj._name)
  File "/g/data3/hh5/public/apps/miniconda3/envs/analysis3-23.01/lib/python3.9/multiprocessing/spawn.py", line 154, in get_preparation_data
    _check_not_importing_main()
  File "/g/data3/hh5/public/apps/miniconda3/envs/analysis3-23.01/lib/python3.9/multiprocessing/spawn.py", line 134, in _check_not_importing_main
    raise RuntimeError('''
RuntimeError: 
        An attempt has been made to start a new process before the
        current process has finished its bootstrapping phase.

        This probably means that you are not using fork to start your
        child processes and you have forgotten to use the proper idiom
        in the main module:

            if __name__ == '__main__':
                freeze_support()
                ...

        The "freeze_support()" line can be omitted if the program
        is not going to be frozen to produce an executable.
2023-04-13 17:46:14,419 - distributed.nanny - ERROR - Failed to start process
Traceback (most recent call last):
  File "/g/data3/hh5/public/apps/miniconda3/envs/analysis3-23.01/lib/python3.9/site-packages/distributed/nanny.py", line 442, in instantiate
    result = await self.process.start()
  File "/g/data3/hh5/public/apps/miniconda3/envs/analysis3-23.01/lib/python3.9/site-packages/distributed/nanny.py", line 711, in start
    await self.process.start()
  File "/g/data3/hh5/public/apps/miniconda3/envs/analysis3-23.01/lib/python3.9/site-packages/distributed/process.py", line 55, in _call_and_set_future
    res = func(*args, **kwargs)
  File "/g/data3/hh5/public/apps/miniconda3/envs/analysis3-23.01/lib/python3.9/site-packages/distributed/process.py", line 215, in _start
    process.start()
  File "/g/data3/hh5/public/apps/miniconda3/envs/analysis3-23.01/lib/python3.9/multiprocessing/process.py", line 121, in start
    self._popen = self._Popen(self)
  File "/g/data3/hh5/public/apps/miniconda3/envs/analysis3-23.01/lib/python3.9/multiprocessing/context.py", line 284, in _Popen
    return Popen(process_obj)
  File "/g/data3/hh5/public/apps/miniconda3/envs/analysis3-23.01/lib/python3.9/multiprocessing/popen_spawn_posix.py", line 32, in __init__
    super().__init__(process_obj)
  File "/g/data3/hh5/public/apps/miniconda3/envs/analysis3-23.01/lib/python3.9/multiprocessing/popen_fork.py", line 19, in __init__
    self._launch(process_obj)
  File "/g/data3/hh5/public/apps/miniconda3/envs/analysis3-23.01/lib/python3.9/multiprocessing/popen_spawn_posix.py", line 42, in _launch
    prep_data = spawn.get_preparation_data(process_obj._name)
  File "/g/data3/hh5/public/apps/miniconda3/envs/analysis3-23.01/lib/python3.9/multiprocessing/spawn.py", line 154, in get_preparation_data
    _check_not_importing_main()
  File "/g/data3/hh5/public/apps/miniconda3/envs/analysis3-23.01/lib/python3.9/multiprocessing/spawn.py", line 134, in _check_not_importing_main
    raise RuntimeError('''
RuntimeError: 
        An attempt has been made to start a new process before the
        current process has finished its bootstrapping phase.

        This probably means that you are not using fork to start your
        child processes and you have forgotten to use the proper idiom
        in the main module:

            if __name__ == '__main__':
                freeze_support()
                ...

        The "freeze_support()" line can be omitted if the program
        is not going to be frozen to produce an executable.
2023-04-13 17:46:14,419 - distributed.nanny - ERROR - Failed to start process
Traceback (most recent call last):
  File "/g/data3/hh5/public/apps/miniconda3/envs/analysis3-23.01/lib/python3.9/site-packages/distributed/nanny.py", line 442, in instantiate
    result = await self.process.start()
  File "/g/data3/hh5/public/apps/miniconda3/envs/analysis3-23.01/lib/python3.9/site-packages/distributed/nanny.py", line 711, in start
    await self.process.start()
  File "/g/data3/hh5/public/apps/miniconda3/envs/analysis3-23.01/lib/python3.9/site-packages/distributed/process.py", line 55, in _call_and_set_future
    res = func(*args, **kwargs)
  File "/g/data3/hh5/public/apps/miniconda3/envs/analysis3-23.01/lib/python3.9/site-packages/distributed/process.py", line 215, in _start
    process.start()
  File "/g/data3/hh5/public/apps/miniconda3/envs/analysis3-23.01/lib/python3.9/multiprocessing/process.py", line 121, in start
    self._popen = self._Popen(self)
  File "/g/data3/hh5/public/apps/miniconda3/envs/analysis3-23.01/lib/python3.9/multiprocessing/context.py", line 284, in _Popen
    return Popen(process_obj)
  File "/g/data3/hh5/public/apps/miniconda3/envs/analysis3-23.01/lib/python3.9/multiprocessing/popen_spawn_posix.py", line 32, in __init__
    super().__init__(process_obj)
  File "/g/data3/hh5/public/apps/miniconda3/envs/analysis3-23.01/lib/python3.9/multiprocessing/popen_fork.py", line 19, in __init__
    self._launch(process_obj)
  File "/g/data3/hh5/public/apps/miniconda3/envs/analysis3-23.01/lib/python3.9/multiprocessing/popen_spawn_posix.py", line 42, in _launch
    prep_data = spawn.get_preparation_data(process_obj._name)
  File "/g/data3/hh5/public/apps/miniconda3/envs/analysis3-23.01/lib/python3.9/multiprocessing/spawn.py", line 154, in get_preparation_data
    _check_not_importing_main()
  File "/g/data3/hh5/public/apps/miniconda3/envs/analysis3-23.01/lib/python3.9/multiprocessing/spawn.py", line 134, in _check_not_importing_main
    raise RuntimeError('''
RuntimeError: 
        An attempt has been made to start a new process before the
        current process has finished its bootstrapping phase.

        This probably means that you are not using fork to start your
        child processes and you have forgotten to use the proper idiom
        in the main module:

            if __name__ == '__main__':
                freeze_support()
                ...

        The "freeze_support()" line can be omitted if the program
        is not going to be frozen to produce an executable.
2023-04-13 17:46:14,419 - distributed.nanny - ERROR - Failed to start process
Traceback (most recent call last):
  File "/g/data3/hh5/public/apps/miniconda3/envs/analysis3-23.01/lib/python3.9/site-packages/distributed/nanny.py", line 442, in instantiate
    result = await self.process.start()
  File "/g/data3/hh5/public/apps/miniconda3/envs/analysis3-23.01/lib/python3.9/site-packages/distributed/nanny.py", line 711, in start
    await self.process.start()
  File "/g/data3/hh5/public/apps/miniconda3/envs/analysis3-23.01/lib/python3.9/site-packages/distributed/process.py", line 55, in _call_and_set_future
    res = func(*args, **kwargs)
  File "/g/data3/hh5/public/apps/miniconda3/envs/analysis3-23.01/lib/python3.9/site-packages/distributed/process.py", line 215, in _start
    process.start()
  File "/g/data3/hh5/public/apps/miniconda3/envs/analysis3-23.01/lib/python3.9/multiprocessing/process.py", line 121, in start
    self._popen = self._Popen(self)
  File "/g/data3/hh5/public/apps/miniconda3/envs/analysis3-23.01/lib/python3.9/multiprocessing/context.py", line 284, in _Popen
    return Popen(process_obj)
  File "/g/data3/hh5/public/apps/miniconda3/envs/analysis3-23.01/lib/python3.9/multiprocessing/popen_spawn_posix.py", line 32, in __init__
    super().__init__(process_obj)
  File "/g/data3/hh5/public/apps/miniconda3/envs/analysis3-23.01/lib/python3.9/multiprocessing/popen_fork.py", line 19, in __init__
    self._launch(process_obj)
  File "/g/data3/hh5/public/apps/miniconda3/envs/analysis3-23.01/lib/python3.9/multiprocessing/popen_spawn_posix.py", line 42, in _launch
    prep_data = spawn.get_preparation_data(process_obj._name)
  File "/g/data3/hh5/public/apps/miniconda3/envs/analysis3-23.01/lib/python3.9/multiprocessing/spawn.py", line 154, in get_preparation_data
    _check_not_importing_main()
  File "/g/data3/hh5/public/apps/miniconda3/envs/analysis3-23.01/lib/python3.9/multiprocessing/spawn.py", line 134, in _check_not_importing_main
    raise RuntimeError('''
RuntimeError: 
        An attempt has been made to start a new process before the
        current process has finished its bootstrapping phase.

        This probably means that you are not using fork to start your
        child processes and you have forgotten to use the proper idiom
        in the main module:

            if __name__ == '__main__':
                freeze_support()
                ...

        The "freeze_support()" line can be omitted if the program
        is not going to be frozen to produce an executable.
2023-04-13 17:46:14,419 - distributed.nanny - ERROR - Failed to start process
Traceback (most recent call last):
  File "/g/data3/hh5/public/apps/miniconda3/envs/analysis3-23.01/lib/python3.9/site-packages/distributed/nanny.py", line 442, in instantiate
    result = await self.process.start()
  File "/g/data3/hh5/public/apps/miniconda3/envs/analysis3-23.01/lib/python3.9/site-packages/distributed/nanny.py", line 711, in start
    await self.process.start()
  File "/g/data3/hh5/public/apps/miniconda3/envs/analysis3-23.01/lib/python3.9/site-packages/distributed/process.py", line 55, in _call_and_set_future
    res = func(*args, **kwargs)
  File "/g/data3/hh5/public/apps/miniconda3/envs/analysis3-23.01/lib/python3.9/site-packages/distributed/process.py", line 215, in _start
    process.start()
  File "/g/data3/hh5/public/apps/miniconda3/envs/analysis3-23.01/lib/python3.9/multiprocessing/process.py", line 121, in start
    self._popen = self._Popen(self)
  File "/g/data3/hh5/public/apps/miniconda3/envs/analysis3-23.01/lib/python3.9/multiprocessing/context.py", line 284, in _Popen
    return Popen(process_obj)
  File "/g/data3/hh5/public/apps/miniconda3/envs/analysis3-23.01/lib/python3.9/multiprocessing/popen_spawn_posix.py", line 32, in __init__
    super().__init__(process_obj)
  File "/g/data3/hh5/public/apps/miniconda3/envs/analysis3-23.01/lib/python3.9/multiprocessing/popen_fork.py", line 19, in __init__
    self._launch(process_obj)
  File "/g/data3/hh5/public/apps/miniconda3/envs/analysis3-23.01/lib/python3.9/multiprocessing/popen_spawn_posix.py", line 42, in _launch
    prep_data = spawn.get_preparation_data(process_obj._name)
  File "/g/data3/hh5/public/apps/miniconda3/envs/analysis3-23.01/lib/python3.9/multiprocessing/spawn.py", line 154, in get_preparation_data
    _check_not_importing_main()
  File "/g/data3/hh5/public/apps/miniconda3/envs/analysis3-23.01/lib/python3.9/multiprocessing/spawn.py", line 134, in _check_not_importing_main
    raise RuntimeError('''
RuntimeError: 
        An attempt has been made to start a new process before the
        current process has finished its bootstrapping phase.

        This probably means that you are not using fork to start your
        child processes and you have forgotten to use the proper idiom
        in the main module:

            if __name__ == '__main__':
                freeze_support()
                ...

        The "freeze_support()" line can be omitted if the program
        is not going to be frozen to produce an executable.
2023-04-13 17:46:14,419 - distributed.nanny - ERROR - Failed to start process
Traceback (most recent call last):
  File "/g/data3/hh5/public/apps/miniconda3/envs/analysis3-23.01/lib/python3.9/site-packages/distributed/nanny.py", line 442, in instantiate
    result = await self.process.start()
  File "/g/data3/hh5/public/apps/miniconda3/envs/analysis3-23.01/lib/python3.9/site-packages/distributed/nanny.py", line 711, in start
    await self.process.start()
  File "/g/data3/hh5/public/apps/miniconda3/envs/analysis3-23.01/lib/python3.9/site-packages/distributed/process.py", line 55, in _call_and_set_future
    res = func(*args, **kwargs)
  File "/g/data3/hh5/public/apps/miniconda3/envs/analysis3-23.01/lib/python3.9/site-packages/distributed/process.py", line 215, in _start
    process.start()
  File "/g/data3/hh5/public/apps/miniconda3/envs/analysis3-23.01/lib/python3.9/multiprocessing/process.py", line 121, in start
    self._popen = self._Popen(self)
  File "/g/data3/hh5/public/apps/miniconda3/envs/analysis3-23.01/lib/python3.9/multiprocessing/context.py", line 284, in _Popen
    return Popen(process_obj)
  File "/g/data3/hh5/public/apps/miniconda3/envs/analysis3-23.01/lib/python3.9/multiprocessing/popen_spawn_posix.py", line 32, in __init__
    super().__init__(process_obj)
  File "/g/data3/hh5/public/apps/miniconda3/envs/analysis3-23.01/lib/python3.9/multiprocessing/popen_fork.py", line 19, in __init__
    self._launch(process_obj)
  File "/g/data3/hh5/public/apps/miniconda3/envs/analysis3-23.01/lib/python3.9/multiprocessing/popen_spawn_posix.py", line 42, in _launch
    prep_data = spawn.get_preparation_data(process_obj._name)
  File "/g/data3/hh5/public/apps/miniconda3/envs/analysis3-23.01/lib/python3.9/multiprocessing/spawn.py", line 154, in get_preparation_data
    _check_not_importing_main()
  File "/g/data3/hh5/public/apps/miniconda3/envs/analysis3-23.01/lib/python3.9/multiprocessing/spawn.py", line 134, in _check_not_importing_main
    raise RuntimeError('''
RuntimeError: 
        An attempt has been made to start a new process before the
        current process has finished its bootstrapping phase.

        This probably means that you are not using fork to start your
        child processes and you have forgotten to use the proper idiom
        in the main module:

            if __name__ == '__main__':
                freeze_support()
                ...

        The "freeze_support()" line can be omitted if the program
        is not going to be frozen to produce an executable.
2023-04-13 17:46:14,419 - distributed.nanny - ERROR - Failed to start process
Traceback (most recent call last):
  File "/g/data3/hh5/public/apps/miniconda3/envs/analysis3-23.01/lib/python3.9/site-packages/distributed/nanny.py", line 442, in instantiate
    result = await self.process.start()
  File "/g/data3/hh5/public/apps/miniconda3/envs/analysis3-23.01/lib/python3.9/site-packages/distributed/nanny.py", line 711, in start
    await self.process.start()
  File "/g/data3/hh5/public/apps/miniconda3/envs/analysis3-23.01/lib/python3.9/site-packages/distributed/process.py", line 55, in _call_and_set_future
    res = func(*args, **kwargs)
  File "/g/data3/hh5/public/apps/miniconda3/envs/analysis3-23.01/lib/python3.9/site-packages/distributed/process.py", line 215, in _start
    process.start()
  File "/g/data3/hh5/public/apps/miniconda3/envs/analysis3-23.01/lib/python3.9/multiprocessing/process.py", line 121, in start
    self._popen = self._Popen(self)
  File "/g/data3/hh5/public/apps/miniconda3/envs/analysis3-23.01/lib/python3.9/multiprocessing/context.py", line 284, in _Popen
    return Popen(process_obj)
  File "/g/data3/hh5/public/apps/miniconda3/envs/analysis3-23.01/lib/python3.9/multiprocessing/popen_spawn_posix.py", line 32, in __init__
    super().__init__(process_obj)
  File "/g/data3/hh5/public/apps/miniconda3/envs/analysis3-23.01/lib/python3.9/multiprocessing/popen_fork.py", line 19, in __init__
    self._launch(process_obj)
  File "/g/data3/hh5/public/apps/miniconda3/envs/analysis3-23.01/lib/python3.9/multiprocessing/popen_spawn_posix.py", line 42, in _launch
    prep_data = spawn.get_preparation_data(process_obj._name)
  File "/g/data3/hh5/public/apps/miniconda3/envs/analysis3-23.01/lib/python3.9/multiprocessing/spawn.py", line 154, in get_preparation_data
    _check_not_importing_main()
  File "/g/data3/hh5/public/apps/miniconda3/envs/analysis3-23.01/lib/python3.9/multiprocessing/spawn.py", line 134, in _check_not_importing_main
    raise RuntimeError('''
RuntimeError: 
        An attempt has been made to start a new process before the
        current process has finished its bootstrapping phase.

        This probably means that you are not using fork to start your
        child processes and you have forgotten to use the proper idiom
        in the main module:

            if __name__ == '__main__':
                freeze_support()
                ...

        The "freeze_support()" line can be omitted if the program
        is not going to be frozen to produce an executable.
2023-04-13 17:46:14,419 - distributed.nanny - ERROR - Failed to start process
Traceback (most recent call last):
  File "/g/data3/hh5/public/apps/miniconda3/envs/analysis3-23.01/lib/python3.9/site-packages/distributed/nanny.py", line 442, in instantiate
    result = await self.process.start()
  File "/g/data3/hh5/public/apps/miniconda3/envs/analysis3-23.01/lib/python3.9/site-packages/distributed/nanny.py", line 711, in start
    await self.process.start()
  File "/g/data3/hh5/public/apps/miniconda3/envs/analysis3-23.01/lib/python3.9/site-packages/distributed/process.py", line 55, in _call_and_set_future
    res = func(*args, **kwargs)
  File "/g/data3/hh5/public/apps/miniconda3/envs/analysis3-23.01/lib/python3.9/site-packages/distributed/process.py", line 215, in _start
    process.start()
  File "/g/data3/hh5/public/apps/miniconda3/envs/analysis3-23.01/lib/python3.9/multiprocessing/process.py", line 121, in start
    self._popen = self._Popen(self)
  File "/g/data3/hh5/public/apps/miniconda3/envs/analysis3-23.01/lib/python3.9/multiprocessing/context.py", line 284, in _Popen
    return Popen(process_obj)
  File "/g/data3/hh5/public/apps/miniconda3/envs/analysis3-23.01/lib/python3.9/multiprocessing/popen_spawn_posix.py", line 32, in __init__
    super().__init__(process_obj)
  File "/g/data3/hh5/public/apps/miniconda3/envs/analysis3-23.01/lib/python3.9/multiprocessing/popen_fork.py", line 19, in __init__
    self._launch(process_obj)
  File "/g/data3/hh5/public/apps/miniconda3/envs/analysis3-23.01/lib/python3.9/multiprocessing/popen_spawn_posix.py", line 42, in _launch
    prep_data = spawn.get_preparation_data(process_obj._name)
  File "/g/data3/hh5/public/apps/miniconda3/envs/analysis3-23.01/lib/python3.9/multiprocessing/spawn.py", line 154, in get_preparation_data
    _check_not_importing_main()
  File "/g/data3/hh5/public/apps/miniconda3/envs/analysis3-23.01/lib/python3.9/multiprocessing/spawn.py", line 134, in _check_not_importing_main
    raise RuntimeError('''
RuntimeError: 
        An attempt has been made to start a new process before the
        current process has finished its bootstrapping phase.

        This probably means that you are not using fork to start your
        child processes and you have forgotten to use the proper idiom
        in the main module:

            if __name__ == '__main__':
                freeze_support()
                ...

        The "freeze_support()" line can be omitted if the program
        is not going to be frozen to produce an executable.
2023-04-13 17:46:14,419 - distributed.nanny - ERROR - Failed to start process
Traceback (most recent call last):
  File "/g/data3/hh5/public/apps/miniconda3/envs/analysis3-23.01/lib/python3.9/site-packages/distributed/nanny.py", line 442, in instantiate
    result = await self.process.start()
  File "/g/data3/hh5/public/apps/miniconda3/envs/analysis3-23.01/lib/python3.9/site-packages/distributed/nanny.py", line 711, in start
    await self.process.start()
  File "/g/data3/hh5/public/apps/miniconda3/envs/analysis3-23.01/lib/python3.9/site-packages/distributed/process.py", line 55, in _call_and_set_future
    res = func(*args, **kwargs)
  File "/g/data3/hh5/public/apps/miniconda3/envs/analysis3-23.01/lib/python3.9/site-packages/distributed/process.py", line 215, in _start
    process.start()
  File "/g/data3/hh5/public/apps/miniconda3/envs/analysis3-23.01/lib/python3.9/multiprocessing/process.py", line 121, in start
    self._popen = self._Popen(self)
  File "/g/data3/hh5/public/apps/miniconda3/envs/analysis3-23.01/lib/python3.9/multiprocessing/context.py", line 284, in _Popen
    return Popen(process_obj)
  File "/g/data3/hh5/public/apps/miniconda3/envs/analysis3-23.01/lib/python3.9/multiprocessing/popen_spawn_posix.py", line 32, in __init__
    super().__init__(process_obj)
  File "/g/data3/hh5/public/apps/miniconda3/envs/analysis3-23.01/lib/python3.9/multiprocessing/popen_fork.py", line 19, in __init__
    self._launch(process_obj)
  File "/g/data3/hh5/public/apps/miniconda3/envs/analysis3-23.01/lib/python3.9/multiprocessing/popen_spawn_posix.py", line 42, in _launch
    prep_data = spawn.get_preparation_data(process_obj._name)
  File "/g/data3/hh5/public/apps/miniconda3/envs/analysis3-23.01/lib/python3.9/multiprocessing/spawn.py", line 154, in get_preparation_data
    _check_not_importing_main()
  File "/g/data3/hh5/public/apps/miniconda3/envs/analysis3-23.01/lib/python3.9/multiprocessing/spawn.py", line 134, in _check_not_importing_main
    raise RuntimeError('''
RuntimeError: 
        An attempt has been made to start a new process before the
        current process has finished its bootstrapping phase.

        This probably means that you are not using fork to start your
        child processes and you have forgotten to use the proper idiom
        in the main module:

            if __name__ == '__main__':
                freeze_support()
                ...

        The "freeze_support()" line can be omitted if the program
        is not going to be frozen to produce an executable.
2023-04-13 17:46:14,419 - distributed.nanny - ERROR - Failed to start process
Traceback (most recent call last):
  File "/g/data3/hh5/public/apps/miniconda3/envs/analysis3-23.01/lib/python3.9/site-packages/distributed/nanny.py", line 442, in instantiate
    result = await self.process.start()
  File "/g/data3/hh5/public/apps/miniconda3/envs/analysis3-23.01/lib/python3.9/site-packages/distributed/nanny.py", line 711, in start
    await self.process.start()
  File "/g/data3/hh5/public/apps/miniconda3/envs/analysis3-23.01/lib/python3.9/site-packages/distributed/process.py", line 55, in _call_and_set_future
    res = func(*args, **kwargs)
  File "/g/data3/hh5/public/apps/miniconda3/envs/analysis3-23.01/lib/python3.9/site-packages/distributed/process.py", line 215, in _start
    process.start()
  File "/g/data3/hh5/public/apps/miniconda3/envs/analysis3-23.01/lib/python3.9/multiprocessing/process.py", line 121, in start
    self._popen = self._Popen(self)
  File "/g/data3/hh5/public/apps/miniconda3/envs/analysis3-23.01/lib/python3.9/multiprocessing/context.py", line 284, in _Popen
    return Popen(process_obj)
  File "/g/data3/hh5/public/apps/miniconda3/envs/analysis3-23.01/lib/python3.9/multiprocessing/popen_spawn_posix.py", line 32, in __init__
    super().__init__(process_obj)
  File "/g/data3/hh5/public/apps/miniconda3/envs/analysis3-23.01/lib/python3.9/multiprocessing/popen_fork.py", line 19, in __init__
    self._launch(process_obj)
  File "/g/data3/hh5/public/apps/miniconda3/envs/analysis3-23.01/lib/python3.9/multiprocessing/popen_spawn_posix.py", line 42, in _launch
    prep_data = spawn.get_preparation_data(process_obj._name)
  File "/g/data3/hh5/public/apps/miniconda3/envs/analysis3-23.01/lib/python3.9/multiprocessing/spawn.py", line 154, in get_preparation_data
    _check_not_importing_main()
  File "/g/data3/hh5/public/apps/miniconda3/envs/analysis3-23.01/lib/python3.9/multiprocessing/spawn.py", line 134, in _check_not_importing_main
    raise RuntimeError('''
RuntimeError: 
        An attempt has been made to start a new process before the
        current process has finished its bootstrapping phase.

        This probably means that you are not using fork to start your
        child processes and you have forgotten to use the proper idiom
        in the main module:

            if __name__ == '__main__':
                freeze_support()
                ...

        The "freeze_support()" line can be omitted if the program
        is not going to be frozen to produce an executable.
2023-04-13 17:46:14,360 - distributed.nanny - ERROR - Failed to start process
Traceback (most recent call last):
  File "/g/data3/hh5/public/apps/miniconda3/envs/analysis3-23.01/lib/python3.9/site-packages/distributed/nanny.py", line 442, in instantiate
    result = await self.process.start()
  File "/g/data3/hh5/public/apps/miniconda3/envs/analysis3-23.01/lib/python3.9/site-packages/distributed/nanny.py", line 711, in start
    await self.process.start()
  File "/g/data3/hh5/public/apps/miniconda3/envs/analysis3-23.01/lib/python3.9/site-packages/distributed/process.py", line 55, in _call_and_set_future
    res = func(*args, **kwargs)
  File "/g/data3/hh5/public/apps/miniconda3/envs/analysis3-23.01/lib/python3.9/site-packages/distributed/process.py", line 215, in _start
    process.start()
  File "/g/data3/hh5/public/apps/miniconda3/envs/analysis3-23.01/lib/python3.9/multiprocessing/process.py", line 121, in start
    self._popen = self._Popen(self)
  File "/g/data3/hh5/public/apps/miniconda3/envs/analysis3-23.01/lib/python3.9/multiprocessing/context.py", line 284, in _Popen
    return Popen(process_obj)
  File "/g/data3/hh5/public/apps/miniconda3/envs/analysis3-23.01/lib/python3.9/multiprocessing/popen_spawn_posix.py", line 32, in __init__
    super().__init__(process_obj)
  File "/g/data3/hh5/public/apps/miniconda3/envs/analysis3-23.01/lib/python3.9/multiprocessing/popen_fork.py", line 19, in __init__
    self._launch(process_obj)
  File "/g/data3/hh5/public/apps/miniconda3/envs/analysis3-23.01/lib/python3.9/multiprocessing/popen_spawn_posix.py", line 42, in _launch
    prep_data = spawn.get_preparation_data(process_obj._name)
  File "/g/data3/hh5/public/apps/miniconda3/envs/analysis3-23.01/lib/python3.9/multiprocessing/spawn.py", line 154, in get_preparation_data
    _check_not_importing_main()
  File "/g/data3/hh5/public/apps/miniconda3/envs/analysis3-23.01/lib/python3.9/multiprocessing/spawn.py", line 134, in _check_not_importing_main
    raise RuntimeError('''
RuntimeError: 
        An attempt has been made to start a new process before the
        current process has finished its bootstrapping phase.

        This probably means that you are not using fork to start your
        child processes and you have forgotten to use the proper idiom
        in the main module:

            if __name__ == '__main__':
                freeze_support()
                ...

        The "freeze_support()" line can be omitted if the program
        is not going to be frozen to produce an executable.
2023-04-13 17:46:14,419 - distributed.nanny - ERROR - Failed to start process
Traceback (most recent call last):
  File "/g/data3/hh5/public/apps/miniconda3/envs/analysis3-23.01/lib/python3.9/site-packages/distributed/nanny.py", line 442, in instantiate
    result = await self.process.start()
  File "/g/data3/hh5/public/apps/miniconda3/envs/analysis3-23.01/lib/python3.9/site-packages/distributed/nanny.py", line 711, in start
    await self.process.start()
  File "/g/data3/hh5/public/apps/miniconda3/envs/analysis3-23.01/lib/python3.9/site-packages/distributed/process.py", line 55, in _call_and_set_future
    res = func(*args, **kwargs)
  File "/g/data3/hh5/public/apps/miniconda3/envs/analysis3-23.01/lib/python3.9/site-packages/distributed/process.py", line 215, in _start
    process.start()
  File "/g/data3/hh5/public/apps/miniconda3/envs/analysis3-23.01/lib/python3.9/multiprocessing/process.py", line 121, in start
    self._popen = self._Popen(self)
  File "/g/data3/hh5/public/apps/miniconda3/envs/analysis3-23.01/lib/python3.9/multiprocessing/context.py", line 284, in _Popen
    return Popen(process_obj)
  File "/g/data3/hh5/public/apps/miniconda3/envs/analysis3-23.01/lib/python3.9/multiprocessing/popen_spawn_posix.py", line 32, in __init__
    super().__init__(process_obj)
  File "/g/data3/hh5/public/apps/miniconda3/envs/analysis3-23.01/lib/python3.9/multiprocessing/popen_fork.py", line 19, in __init__
    self._launch(process_obj)
  File "/g/data3/hh5/public/apps/miniconda3/envs/analysis3-23.01/lib/python3.9/multiprocessing/popen_spawn_posix.py", line 42, in _launch
    prep_data = spawn.get_preparation_data(process_obj._name)
  File "/g/data3/hh5/public/apps/miniconda3/envs/analysis3-23.01/lib/python3.9/multiprocessing/spawn.py", line 154, in get_preparation_data
    _check_not_importing_main()
  File "/g/data3/hh5/public/apps/miniconda3/envs/analysis3-23.01/lib/python3.9/multiprocessing/spawn.py", line 134, in _check_not_importing_main
    raise RuntimeError('''
RuntimeError: 
        An attempt has been made to start a new process before the
        current process has finished its bootstrapping phase.

        This probably means that you are not using fork to start your
        child processes and you have forgotten to use the proper idiom
        in the main module:

            if __name__ == '__main__':
                freeze_support()
                ...

        The "freeze_support()" line can be omitted if the program
        is not going to be frozen to produce an executable.
2023-04-13 17:46:14,419 - distributed.nanny - ERROR - Failed to start process
Traceback (most recent call last):
  File "/g/data3/hh5/public/apps/miniconda3/envs/analysis3-23.01/lib/python3.9/site-packages/distributed/nanny.py", line 442, in instantiate
    result = await self.process.start()
  File "/g/data3/hh5/public/apps/miniconda3/envs/analysis3-23.01/lib/python3.9/site-packages/distributed/nanny.py", line 711, in start
    await self.process.start()
  File "/g/data3/hh5/public/apps/miniconda3/envs/analysis3-23.01/lib/python3.9/site-packages/distributed/process.py", line 55, in _call_and_set_future
    res = func(*args, **kwargs)
  File "/g/data3/hh5/public/apps/miniconda3/envs/analysis3-23.01/lib/python3.9/site-packages/distributed/process.py", line 215, in _start
    process.start()
  File "/g/data3/hh5/public/apps/miniconda3/envs/analysis3-23.01/lib/python3.9/multiprocessing/process.py", line 121, in start
    self._popen = self._Popen(self)
  File "/g/data3/hh5/public/apps/miniconda3/envs/analysis3-23.01/lib/python3.9/multiprocessing/context.py", line 284, in _Popen
    return Popen(process_obj)
  File "/g/data3/hh5/public/apps/miniconda3/envs/analysis3-23.01/lib/python3.9/multiprocessing/popen_spawn_posix.py", line 32, in __init__
    super().__init__(process_obj)
  File "/g/data3/hh5/public/apps/miniconda3/envs/analysis3-23.01/lib/python3.9/multiprocessing/popen_fork.py", line 19, in __init__
    self._launch(process_obj)
  File "/g/data3/hh5/public/apps/miniconda3/envs/analysis3-23.01/lib/python3.9/multiprocessing/popen_spawn_posix.py", line 42, in _launch
    prep_data = spawn.get_preparation_data(process_obj._name)
  File "/g/data3/hh5/public/apps/miniconda3/envs/analysis3-23.01/lib/python3.9/multiprocessing/spawn.py", line 154, in get_preparation_data
    _check_not_importing_main()
  File "/g/data3/hh5/public/apps/miniconda3/envs/analysis3-23.01/lib/python3.9/multiprocessing/spawn.py", line 134, in _check_not_importing_main
    raise RuntimeError('''
RuntimeError: 
        An attempt has been made to start a new process before the
        current process has finished its bootstrapping phase.

        This probably means that you are not using fork to start your
        child processes and you have forgotten to use the proper idiom
        in the main module:

            if __name__ == '__main__':
                freeze_support()
                ...

        The "freeze_support()" line can be omitted if the program
        is not going to be frozen to produce an executable.
2023-04-13 17:46:14,420 - distributed.nanny - ERROR - Failed to start process
Traceback (most recent call last):
  File "/g/data3/hh5/public/apps/miniconda3/envs/analysis3-23.01/lib/python3.9/site-packages/distributed/nanny.py", line 442, in instantiate
    result = await self.process.start()
  File "/g/data3/hh5/public/apps/miniconda3/envs/analysis3-23.01/lib/python3.9/site-packages/distributed/nanny.py", line 711, in start
    await self.process.start()
  File "/g/data3/hh5/public/apps/miniconda3/envs/analysis3-23.01/lib/python3.9/site-packages/distributed/process.py", line 55, in _call_and_set_future
    res = func(*args, **kwargs)
  File "/g/data3/hh5/public/apps/miniconda3/envs/analysis3-23.01/lib/python3.9/site-packages/distributed/process.py", line 215, in _start
    process.start()
  File "/g/data3/hh5/public/apps/miniconda3/envs/analysis3-23.01/lib/python3.9/multiprocessing/process.py", line 121, in start
    self._popen = self._Popen(self)
  File "/g/data3/hh5/public/apps/miniconda3/envs/analysis3-23.01/lib/python3.9/multiprocessing/context.py", line 284, in _Popen
    return Popen(process_obj)
  File "/g/data3/hh5/public/apps/miniconda3/envs/analysis3-23.01/lib/python3.9/multiprocessing/popen_spawn_posix.py", line 32, in __init__
    super().__init__(process_obj)
  File "/g/data3/hh5/public/apps/miniconda3/envs/analysis3-23.01/lib/python3.9/multiprocessing/popen_fork.py", line 19, in __init__
    self._launch(process_obj)
  File "/g/data3/hh5/public/apps/miniconda3/envs/analysis3-23.01/lib/python3.9/multiprocessing/popen_spawn_posix.py", line 42, in _launch
    prep_data = spawn.get_preparation_data(process_obj._name)
  File "/g/data3/hh5/public/apps/miniconda3/envs/analysis3-23.01/lib/python3.9/multiprocessing/spawn.py", line 154, in get_preparation_data
    _check_not_importing_main()
  File "/g/data3/hh5/public/apps/miniconda3/envs/analysis3-23.01/lib/python3.9/multiprocessing/spawn.py", line 134, in _check_not_importing_main
    raise RuntimeError('''
RuntimeError: 
        An attempt has been made to start a new process before the
        current process has finished its bootstrapping phase.

        This probably means that you are not using fork to start your
        child processes and you have forgotten to use the proper idiom
        in the main module:

            if __name__ == '__main__':
                freeze_support()
                ...

        The "freeze_support()" line can be omitted if the program
        is not going to be frozen to produce an executable.
2023-04-13 17:46:14,420 - distributed.nanny - ERROR - Failed to start process
Traceback (most recent call last):
  File "/g/data3/hh5/public/apps/miniconda3/envs/analysis3-23.01/lib/python3.9/site-packages/distributed/nanny.py", line 442, in instantiate
    result = await self.process.start()
  File "/g/data3/hh5/public/apps/miniconda3/envs/analysis3-23.01/lib/python3.9/site-packages/distributed/nanny.py", line 711, in start
    await self.process.start()
  File "/g/data3/hh5/public/apps/miniconda3/envs/analysis3-23.01/lib/python3.9/site-packages/distributed/process.py", line 55, in _call_and_set_future
    res = func(*args, **kwargs)
  File "/g/data3/hh5/public/apps/miniconda3/envs/analysis3-23.01/lib/python3.9/site-packages/distributed/process.py", line 215, in _start
    process.start()
  File "/g/data3/hh5/public/apps/miniconda3/envs/analysis3-23.01/lib/python3.9/multiprocessing/process.py", line 121, in start
    self._popen = self._Popen(self)
  File "/g/data3/hh5/public/apps/miniconda3/envs/analysis3-23.01/lib/python3.9/multiprocessing/context.py", line 284, in _Popen
    return Popen(process_obj)
  File "/g/data3/hh5/public/apps/miniconda3/envs/analysis3-23.01/lib/python3.9/multiprocessing/popen_spawn_posix.py", line 32, in __init__
    super().__init__(process_obj)
  File "/g/data3/hh5/public/apps/miniconda3/envs/analysis3-23.01/lib/python3.9/multiprocessing/popen_fork.py", line 19, in __init__
    self._launch(process_obj)
  File "/g/data3/hh5/public/apps/miniconda3/envs/analysis3-23.01/lib/python3.9/multiprocessing/popen_spawn_posix.py", line 42, in _launch
    prep_data = spawn.get_preparation_data(process_obj._name)
  File "/g/data3/hh5/public/apps/miniconda3/envs/analysis3-23.01/lib/python3.9/multiprocessing/spawn.py", line 154, in get_preparation_data
    _check_not_importing_main()
  File "/g/data3/hh5/public/apps/miniconda3/envs/analysis3-23.01/lib/python3.9/multiprocessing/spawn.py", line 134, in _check_not_importing_main
    raise RuntimeError('''
RuntimeError: 
        An attempt has been made to start a new process before the
        current process has finished its bootstrapping phase.

        This probably means that you are not using fork to start your
        child processes and you have forgotten to use the proper idiom
        in the main module:

            if __name__ == '__main__':
                freeze_support()
                ...

        The "freeze_support()" line can be omitted if the program
        is not going to be frozen to produce an executable.
2023-04-13 17:46:14,420 - distributed.nanny - ERROR - Failed to start process
Traceback (most recent call last):
  File "/g/data3/hh5/public/apps/miniconda3/envs/analysis3-23.01/lib/python3.9/site-packages/distributed/nanny.py", line 442, in instantiate
    result = await self.process.start()
  File "/g/data3/hh5/public/apps/miniconda3/envs/analysis3-23.01/lib/python3.9/site-packages/distributed/nanny.py", line 711, in start
    await self.process.start()
  File "/g/data3/hh5/public/apps/miniconda3/envs/analysis3-23.01/lib/python3.9/site-packages/distributed/process.py", line 55, in _call_and_set_future
    res = func(*args, **kwargs)
  File "/g/data3/hh5/public/apps/miniconda3/envs/analysis3-23.01/lib/python3.9/site-packages/distributed/process.py", line 215, in _start
    process.start()
  File "/g/data3/hh5/public/apps/miniconda3/envs/analysis3-23.01/lib/python3.9/multiprocessing/process.py", line 121, in start
    self._popen = self._Popen(self)
  File "/g/data3/hh5/public/apps/miniconda3/envs/analysis3-23.01/lib/python3.9/multiprocessing/context.py", line 284, in _Popen
    return Popen(process_obj)
  File "/g/data3/hh5/public/apps/miniconda3/envs/analysis3-23.01/lib/python3.9/multiprocessing/popen_spawn_posix.py", line 32, in __init__
    super().__init__(process_obj)
  File "/g/data3/hh5/public/apps/miniconda3/envs/analysis3-23.01/lib/python3.9/multiprocessing/popen_fork.py", line 19, in __init__
    self._launch(process_obj)
  File "/g/data3/hh5/public/apps/miniconda3/envs/analysis3-23.01/lib/python3.9/multiprocessing/popen_spawn_posix.py", line 42, in _launch
    prep_data = spawn.get_preparation_data(process_obj._name)
  File "/g/data3/hh5/public/apps/miniconda3/envs/analysis3-23.01/lib/python3.9/multiprocessing/spawn.py", line 154, in get_preparation_data
    _check_not_importing_main()
  File "/g/data3/hh5/public/apps/miniconda3/envs/analysis3-23.01/lib/python3.9/multiprocessing/spawn.py", line 134, in _check_not_importing_main
    raise RuntimeError('''
RuntimeError: 
        An attempt has been made to start a new process before the
        current process has finished its bootstrapping phase.

        This probably means that you are not using fork to start your
        child processes and you have forgotten to use the proper idiom
        in the main module:

            if __name__ == '__main__':
                freeze_support()
                ...

        The "freeze_support()" line can be omitted if the program
        is not going to be frozen to produce an executable.
2023-04-13 17:46:14,419 - distributed.nanny - ERROR - Failed to start process
Traceback (most recent call last):
  File "/g/data3/hh5/public/apps/miniconda3/envs/analysis3-23.01/lib/python3.9/site-packages/distributed/nanny.py", line 442, in instantiate
    result = await self.process.start()
  File "/g/data3/hh5/public/apps/miniconda3/envs/analysis3-23.01/lib/python3.9/site-packages/distributed/nanny.py", line 711, in start
    await self.process.start()
  File "/g/data3/hh5/public/apps/miniconda3/envs/analysis3-23.01/lib/python3.9/site-packages/distributed/process.py", line 55, in _call_and_set_future
    res = func(*args, **kwargs)
  File "/g/data3/hh5/public/apps/miniconda3/envs/analysis3-23.01/lib/python3.9/site-packages/distributed/process.py", line 215, in _start
    process.start()
  File "/g/data3/hh5/public/apps/miniconda3/envs/analysis3-23.01/lib/python3.9/multiprocessing/process.py", line 121, in start
    self._popen = self._Popen(self)
  File "/g/data3/hh5/public/apps/miniconda3/envs/analysis3-23.01/lib/python3.9/multiprocessing/context.py", line 284, in _Popen
    return Popen(process_obj)
  File "/g/data3/hh5/public/apps/miniconda3/envs/analysis3-23.01/lib/python3.9/multiprocessing/popen_spawn_posix.py", line 32, in __init__
    super().__init__(process_obj)
  File "/g/data3/hh5/public/apps/miniconda3/envs/analysis3-23.01/lib/python3.9/multiprocessing/popen_fork.py", line 19, in __init__
    self._launch(process_obj)
  File "/g/data3/hh5/public/apps/miniconda3/envs/analysis3-23.01/lib/python3.9/multiprocessing/popen_spawn_posix.py", line 42, in _launch
    prep_data = spawn.get_preparation_data(process_obj._name)
  File "/g/data3/hh5/public/apps/miniconda3/envs/analysis3-23.01/lib/python3.9/multiprocessing/spawn.py", line 154, in get_preparation_data
    _check_not_importing_main()
  File "/g/data3/hh5/public/apps/miniconda3/envs/analysis3-23.01/lib/python3.9/multiprocessing/spawn.py", line 134, in _check_not_importing_main
    raise RuntimeError('''
RuntimeError: 
        An attempt has been made to start a new process before the
        current process has finished its bootstrapping phase.

        This probably means that you are not using fork to start your
        child processes and you have forgotten to use the proper idiom
        in the main module:

            if __name__ == '__main__':
                freeze_support()
                ...

        The "freeze_support()" line can be omitted if the program
        is not going to be frozen to produce an executable.
2023-04-13 17:46:14,420 - distributed.nanny - ERROR - Failed to start process
Traceback (most recent call last):
  File "/g/data3/hh5/public/apps/miniconda3/envs/analysis3-23.01/lib/python3.9/site-packages/distributed/nanny.py", line 442, in instantiate
    result = await self.process.start()
  File "/g/data3/hh5/public/apps/miniconda3/envs/analysis3-23.01/lib/python3.9/site-packages/distributed/nanny.py", line 711, in start
    await self.process.start()
  File "/g/data3/hh5/public/apps/miniconda3/envs/analysis3-23.01/lib/python3.9/site-packages/distributed/process.py", line 55, in _call_and_set_future
    res = func(*args, **kwargs)
  File "/g/data3/hh5/public/apps/miniconda3/envs/analysis3-23.01/lib/python3.9/site-packages/distributed/process.py", line 215, in _start
    process.start()
  File "/g/data3/hh5/public/apps/miniconda3/envs/analysis3-23.01/lib/python3.9/multiprocessing/process.py", line 121, in start
    self._popen = self._Popen(self)
  File "/g/data3/hh5/public/apps/miniconda3/envs/analysis3-23.01/lib/python3.9/multiprocessing/context.py", line 284, in _Popen
    return Popen(process_obj)
  File "/g/data3/hh5/public/apps/miniconda3/envs/analysis3-23.01/lib/python3.9/multiprocessing/popen_spawn_posix.py", line 32, in __init__
    super().__init__(process_obj)
  File "/g/data3/hh5/public/apps/miniconda3/envs/analysis3-23.01/lib/python3.9/multiprocessing/popen_fork.py", line 19, in __init__
    self._launch(process_obj)
  File "/g/data3/hh5/public/apps/miniconda3/envs/analysis3-23.01/lib/python3.9/multiprocessing/popen_spawn_posix.py", line 42, in _launch
    prep_data = spawn.get_preparation_data(process_obj._name)
  File "/g/data3/hh5/public/apps/miniconda3/envs/analysis3-23.01/lib/python3.9/multiprocessing/spawn.py", line 154, in get_preparation_data
    _check_not_importing_main()
  File "/g/data3/hh5/public/apps/miniconda3/envs/analysis3-23.01/lib/python3.9/multiprocessing/spawn.py", line 134, in _check_not_importing_main
    raise RuntimeError('''
RuntimeError: 
        An attempt has been made to start a new process before the
        current process has finished its bootstrapping phase.

        This probably means that you are not using fork to start your
        child processes and you have forgotten to use the proper idiom
        in the main module:

            if __name__ == '__main__':
                freeze_support()
                ...

        The "freeze_support()" line can be omitted if the program
        is not going to be frozen to produce an executable.
2023-04-13 17:46:14,420 - distributed.nanny - ERROR - Failed to start process
Traceback (most recent call last):
  File "/g/data3/hh5/public/apps/miniconda3/envs/analysis3-23.01/lib/python3.9/site-packages/distributed/nanny.py", line 442, in instantiate
    result = await self.process.start()
  File "/g/data3/hh5/public/apps/miniconda3/envs/analysis3-23.01/lib/python3.9/site-packages/distributed/nanny.py", line 711, in start
    await self.process.start()
  File "/g/data3/hh5/public/apps/miniconda3/envs/analysis3-23.01/lib/python3.9/site-packages/distributed/process.py", line 55, in _call_and_set_future
    res = func(*args, **kwargs)
  File "/g/data3/hh5/public/apps/miniconda3/envs/analysis3-23.01/lib/python3.9/site-packages/distributed/process.py", line 215, in _start
    process.start()
  File "/g/data3/hh5/public/apps/miniconda3/envs/analysis3-23.01/lib/python3.9/multiprocessing/process.py", line 121, in start
    self._popen = self._Popen(self)
  File "/g/data3/hh5/public/apps/miniconda3/envs/analysis3-23.01/lib/python3.9/multiprocessing/context.py", line 284, in _Popen
    return Popen(process_obj)
  File "/g/data3/hh5/public/apps/miniconda3/envs/analysis3-23.01/lib/python3.9/multiprocessing/popen_spawn_posix.py", line 32, in __init__
    super().__init__(process_obj)
  File "/g/data3/hh5/public/apps/miniconda3/envs/analysis3-23.01/lib/python3.9/multiprocessing/popen_fork.py", line 19, in __init__
    self._launch(process_obj)
  File "/g/data3/hh5/public/apps/miniconda3/envs/analysis3-23.01/lib/python3.9/multiprocessing/popen_spawn_posix.py", line 42, in _launch
    prep_data = spawn.get_preparation_data(process_obj._name)
  File "/g/data3/hh5/public/apps/miniconda3/envs/analysis3-23.01/lib/python3.9/multiprocessing/spawn.py", line 154, in get_preparation_data
    _check_not_importing_main()
  File "/g/data3/hh5/public/apps/miniconda3/envs/analysis3-23.01/lib/python3.9/multiprocessing/spawn.py", line 134, in _check_not_importing_main
    raise RuntimeError('''
RuntimeError: 
        An attempt has been made to start a new process before the
        current process has finished its bootstrapping phase.

        This probably means that you are not using fork to start your
        child processes and you have forgotten to use the proper idiom
        in the main module:

            if __name__ == '__main__':
                freeze_support()
                ...

        The "freeze_support()" line can be omitted if the program
        is not going to be frozen to produce an executable.
2023-04-13 17:46:14,420 - distributed.nanny - ERROR - Failed to start process
Traceback (most recent call last):
  File "/g/data3/hh5/public/apps/miniconda3/envs/analysis3-23.01/lib/python3.9/site-packages/distributed/nanny.py", line 442, in instantiate
    result = await self.process.start()
  File "/g/data3/hh5/public/apps/miniconda3/envs/analysis3-23.01/lib/python3.9/site-packages/distributed/nanny.py", line 711, in start
    await self.process.start()
  File "/g/data3/hh5/public/apps/miniconda3/envs/analysis3-23.01/lib/python3.9/site-packages/distributed/process.py", line 55, in _call_and_set_future
    res = func(*args, **kwargs)
  File "/g/data3/hh5/public/apps/miniconda3/envs/analysis3-23.01/lib/python3.9/site-packages/distributed/process.py", line 215, in _start
    process.start()
  File "/g/data3/hh5/public/apps/miniconda3/envs/analysis3-23.01/lib/python3.9/multiprocessing/process.py", line 121, in start
    self._popen = self._Popen(self)
  File "/g/data3/hh5/public/apps/miniconda3/envs/analysis3-23.01/lib/python3.9/multiprocessing/context.py", line 284, in _Popen
    return Popen(process_obj)
  File "/g/data3/hh5/public/apps/miniconda3/envs/analysis3-23.01/lib/python3.9/multiprocessing/popen_spawn_posix.py", line 32, in __init__
    super().__init__(process_obj)
  File "/g/data3/hh5/public/apps/miniconda3/envs/analysis3-23.01/lib/python3.9/multiprocessing/popen_fork.py", line 19, in __init__
    self._launch(process_obj)
  File "/g/data3/hh5/public/apps/miniconda3/envs/analysis3-23.01/lib/python3.9/multiprocessing/popen_spawn_posix.py", line 42, in _launch
    prep_data = spawn.get_preparation_data(process_obj._name)
  File "/g/data3/hh5/public/apps/miniconda3/envs/analysis3-23.01/lib/python3.9/multiprocessing/spawn.py", line 154, in get_preparation_data
    _check_not_importing_main()
  File "/g/data3/hh5/public/apps/miniconda3/envs/analysis3-23.01/lib/python3.9/multiprocessing/spawn.py", line 134, in _check_not_importing_main
    raise RuntimeError('''
RuntimeError: 
        An attempt has been made to start a new process before the
        current process has finished its bootstrapping phase.

        This probably means that you are not using fork to start your
        child processes and you have forgotten to use the proper idiom
        in the main module:

            if __name__ == '__main__':
                freeze_support()
                ...

        The "freeze_support()" line can be omitted if the program
        is not going to be frozen to produce an executable.
2023-04-13 17:46:14,420 - distributed.nanny - ERROR - Failed to start process
Traceback (most recent call last):
  File "/g/data3/hh5/public/apps/miniconda3/envs/analysis3-23.01/lib/python3.9/site-packages/distributed/nanny.py", line 442, in instantiate
    result = await self.process.start()
  File "/g/data3/hh5/public/apps/miniconda3/envs/analysis3-23.01/lib/python3.9/site-packages/distributed/nanny.py", line 711, in start
    await self.process.start()
  File "/g/data3/hh5/public/apps/miniconda3/envs/analysis3-23.01/lib/python3.9/site-packages/distributed/process.py", line 55, in _call_and_set_future
    res = func(*args, **kwargs)
  File "/g/data3/hh5/public/apps/miniconda3/envs/analysis3-23.01/lib/python3.9/site-packages/distributed/process.py", line 215, in _start
    process.start()
  File "/g/data3/hh5/public/apps/miniconda3/envs/analysis3-23.01/lib/python3.9/multiprocessing/process.py", line 121, in start
    self._popen = self._Popen(self)
  File "/g/data3/hh5/public/apps/miniconda3/envs/analysis3-23.01/lib/python3.9/multiprocessing/context.py", line 284, in _Popen
    return Popen(process_obj)
  File "/g/data3/hh5/public/apps/miniconda3/envs/analysis3-23.01/lib/python3.9/multiprocessing/popen_spawn_posix.py", line 32, in __init__
    super().__init__(process_obj)
  File "/g/data3/hh5/public/apps/miniconda3/envs/analysis3-23.01/lib/python3.9/multiprocessing/popen_fork.py", line 19, in __init__
    self._launch(process_obj)
  File "/g/data3/hh5/public/apps/miniconda3/envs/analysis3-23.01/lib/python3.9/multiprocessing/popen_spawn_posix.py", line 42, in _launch
    prep_data = spawn.get_preparation_data(process_obj._name)
  File "/g/data3/hh5/public/apps/miniconda3/envs/analysis3-23.01/lib/python3.9/multiprocessing/spawn.py", line 154, in get_preparation_data
    _check_not_importing_main()
  File "/g/data3/hh5/public/apps/miniconda3/envs/analysis3-23.01/lib/python3.9/multiprocessing/spawn.py", line 134, in _check_not_importing_main
    raise RuntimeError('''
RuntimeError: 
        An attempt has been made to start a new process before the
        current process has finished its bootstrapping phase.

        This probably means that you are not using fork to start your
        child processes and you have forgotten to use the proper idiom
        in the main module:

            if __name__ == '__main__':
                freeze_support()
                ...

        The "freeze_support()" line can be omitted if the program
        is not going to be frozen to produce an executable.
2023-04-13 17:46:14,420 - distributed.nanny - ERROR - Failed to start process
Traceback (most recent call last):
  File "/g/data3/hh5/public/apps/miniconda3/envs/analysis3-23.01/lib/python3.9/site-packages/distributed/nanny.py", line 442, in instantiate
    result = await self.process.start()
  File "/g/data3/hh5/public/apps/miniconda3/envs/analysis3-23.01/lib/python3.9/site-packages/distributed/nanny.py", line 711, in start
    await self.process.start()
  File "/g/data3/hh5/public/apps/miniconda3/envs/analysis3-23.01/lib/python3.9/site-packages/distributed/process.py", line 55, in _call_and_set_future
    res = func(*args, **kwargs)
  File "/g/data3/hh5/public/apps/miniconda3/envs/analysis3-23.01/lib/python3.9/site-packages/distributed/process.py", line 215, in _start
    process.start()
  File "/g/data3/hh5/public/apps/miniconda3/envs/analysis3-23.01/lib/python3.9/multiprocessing/process.py", line 121, in start
    self._popen = self._Popen(self)
  File "/g/data3/hh5/public/apps/miniconda3/envs/analysis3-23.01/lib/python3.9/multiprocessing/context.py", line 284, in _Popen
    return Popen(process_obj)
  File "/g/data3/hh5/public/apps/miniconda3/envs/analysis3-23.01/lib/python3.9/multiprocessing/popen_spawn_posix.py", line 32, in __init__
    super().__init__(process_obj)
  File "/g/data3/hh5/public/apps/miniconda3/envs/analysis3-23.01/lib/python3.9/multiprocessing/popen_fork.py", line 19, in __init__
    self._launch(process_obj)
  File "/g/data3/hh5/public/apps/miniconda3/envs/analysis3-23.01/lib/python3.9/multiprocessing/popen_spawn_posix.py", line 42, in _launch
    prep_data = spawn.get_preparation_data(process_obj._name)
  File "/g/data3/hh5/public/apps/miniconda3/envs/analysis3-23.01/lib/python3.9/multiprocessing/spawn.py", line 154, in get_preparation_data
    _check_not_importing_main()
  File "/g/data3/hh5/public/apps/miniconda3/envs/analysis3-23.01/lib/python3.9/multiprocessing/spawn.py", line 134, in _check_not_importing_main
    raise RuntimeError('''
RuntimeError: 
        An attempt has been made to start a new process before the
        current process has finished its bootstrapping phase.

        This probably means that you are not using fork to start your
        child processes and you have forgotten to use the proper idiom
        in the main module:

            if __name__ == '__main__':
                freeze_support()
                ...

        The "freeze_support()" line can be omitted if the program
        is not going to be frozen to produce an executable.
2023-04-13 17:46:14,420 - distributed.nanny - ERROR - Failed to start process
Traceback (most recent call last):
  File "/g/data3/hh5/public/apps/miniconda3/envs/analysis3-23.01/lib/python3.9/site-packages/distributed/nanny.py", line 442, in instantiate
    result = await self.process.start()
  File "/g/data3/hh5/public/apps/miniconda3/envs/analysis3-23.01/lib/python3.9/site-packages/distributed/nanny.py", line 711, in start
    await self.process.start()
  File "/g/data3/hh5/public/apps/miniconda3/envs/analysis3-23.01/lib/python3.9/site-packages/distributed/process.py", line 55, in _call_and_set_future
    res = func(*args, **kwargs)
  File "/g/data3/hh5/public/apps/miniconda3/envs/analysis3-23.01/lib/python3.9/site-packages/distributed/process.py", line 215, in _start
    process.start()
  File "/g/data3/hh5/public/apps/miniconda3/envs/analysis3-23.01/lib/python3.9/multiprocessing/process.py", line 121, in start
    self._popen = self._Popen(self)
  File "/g/data3/hh5/public/apps/miniconda3/envs/analysis3-23.01/lib/python3.9/multiprocessing/context.py", line 284, in _Popen
    return Popen(process_obj)
  File "/g/data3/hh5/public/apps/miniconda3/envs/analysis3-23.01/lib/python3.9/multiprocessing/popen_spawn_posix.py", line 32, in __init__
    super().__init__(process_obj)
  File "/g/data3/hh5/public/apps/miniconda3/envs/analysis3-23.01/lib/python3.9/multiprocessing/popen_fork.py", line 19, in __init__
    self._launch(process_obj)
  File "/g/data3/hh5/public/apps/miniconda3/envs/analysis3-23.01/lib/python3.9/multiprocessing/popen_spawn_posix.py", line 42, in _launch
    prep_data = spawn.get_preparation_data(process_obj._name)
  File "/g/data3/hh5/public/apps/miniconda3/envs/analysis3-23.01/lib/python3.9/multiprocessing/spawn.py", line 154, in get_preparation_data
    _check_not_importing_main()
  File "/g/data3/hh5/public/apps/miniconda3/envs/analysis3-23.01/lib/python3.9/multiprocessing/spawn.py", line 134, in _check_not_importing_main
    raise RuntimeError('''
RuntimeError: 
        An attempt has been made to start a new process before the
        current process has finished its bootstrapping phase.

        This probably means that you are not using fork to start your
        child processes and you have forgotten to use the proper idiom
        in the main module:

            if __name__ == '__main__':
                freeze_support()
                ...

        The "freeze_support()" line can be omitted if the program
        is not going to be frozen to produce an executable.
2023-04-13 17:46:14,420 - distributed.nanny - ERROR - Failed to start process
Traceback (most recent call last):
  File "/g/data3/hh5/public/apps/miniconda3/envs/analysis3-23.01/lib/python3.9/site-packages/distributed/nanny.py", line 442, in instantiate
    result = await self.process.start()
  File "/g/data3/hh5/public/apps/miniconda3/envs/analysis3-23.01/lib/python3.9/site-packages/distributed/nanny.py", line 711, in start
    await self.process.start()
  File "/g/data3/hh5/public/apps/miniconda3/envs/analysis3-23.01/lib/python3.9/site-packages/distributed/process.py", line 55, in _call_and_set_future
    res = func(*args, **kwargs)
  File "/g/data3/hh5/public/apps/miniconda3/envs/analysis3-23.01/lib/python3.9/site-packages/distributed/process.py", line 215, in _start
    process.start()
  File "/g/data3/hh5/public/apps/miniconda3/envs/analysis3-23.01/lib/python3.9/multiprocessing/process.py", line 121, in start
    self._popen = self._Popen(self)
  File "/g/data3/hh5/public/apps/miniconda3/envs/analysis3-23.01/lib/python3.9/multiprocessing/context.py", line 284, in _Popen
    return Popen(process_obj)
  File "/g/data3/hh5/public/apps/miniconda3/envs/analysis3-23.01/lib/python3.9/multiprocessing/popen_spawn_posix.py", line 32, in __init__
    super().__init__(process_obj)
  File "/g/data3/hh5/public/apps/miniconda3/envs/analysis3-23.01/lib/python3.9/multiprocessing/popen_fork.py", line 19, in __init__
    self._launch(process_obj)
  File "/g/data3/hh5/public/apps/miniconda3/envs/analysis3-23.01/lib/python3.9/multiprocessing/popen_spawn_posix.py", line 42, in _launch
    prep_data = spawn.get_preparation_data(process_obj._name)
  File "/g/data3/hh5/public/apps/miniconda3/envs/analysis3-23.01/lib/python3.9/multiprocessing/spawn.py", line 154, in get_preparation_data
    _check_not_importing_main()
  File "/g/data3/hh5/public/apps/miniconda3/envs/analysis3-23.01/lib/python3.9/multiprocessing/spawn.py", line 134, in _check_not_importing_main
    raise RuntimeError('''
RuntimeError: 
        An attempt has been made to start a new process before the
        current process has finished its bootstrapping phase.

        This probably means that you are not using fork to start your
        child processes and you have forgotten to use the proper idiom
        in the main module:

            if __name__ == '__main__':
                freeze_support()
                ...

        The "freeze_support()" line can be omitted if the program
        is not going to be frozen to produce an executable.
2023-04-13 17:46:14,420 - distributed.nanny - ERROR - Failed to start process
Traceback (most recent call last):
  File "/g/data3/hh5/public/apps/miniconda3/envs/analysis3-23.01/lib/python3.9/site-packages/distributed/nanny.py", line 442, in instantiate
    result = await self.process.start()
  File "/g/data3/hh5/public/apps/miniconda3/envs/analysis3-23.01/lib/python3.9/site-packages/distributed/nanny.py", line 711, in start
    await self.process.start()
  File "/g/data3/hh5/public/apps/miniconda3/envs/analysis3-23.01/lib/python3.9/site-packages/distributed/process.py", line 55, in _call_and_set_future
    res = func(*args, **kwargs)
  File "/g/data3/hh5/public/apps/miniconda3/envs/analysis3-23.01/lib/python3.9/site-packages/distributed/process.py", line 215, in _start
    process.start()
  File "/g/data3/hh5/public/apps/miniconda3/envs/analysis3-23.01/lib/python3.9/multiprocessing/process.py", line 121, in start
    self._popen = self._Popen(self)
  File "/g/data3/hh5/public/apps/miniconda3/envs/analysis3-23.01/lib/python3.9/multiprocessing/context.py", line 284, in _Popen
    return Popen(process_obj)
  File "/g/data3/hh5/public/apps/miniconda3/envs/analysis3-23.01/lib/python3.9/multiprocessing/popen_spawn_posix.py", line 32, in __init__
    super().__init__(process_obj)
  File "/g/data3/hh5/public/apps/miniconda3/envs/analysis3-23.01/lib/python3.9/multiprocessing/popen_fork.py", line 19, in __init__
    self._launch(process_obj)
  File "/g/data3/hh5/public/apps/miniconda3/envs/analysis3-23.01/lib/python3.9/multiprocessing/popen_spawn_posix.py", line 42, in _launch
    prep_data = spawn.get_preparation_data(process_obj._name)
  File "/g/data3/hh5/public/apps/miniconda3/envs/analysis3-23.01/lib/python3.9/multiprocessing/spawn.py", line 154, in get_preparation_data
    _check_not_importing_main()
  File "/g/data3/hh5/public/apps/miniconda3/envs/analysis3-23.01/lib/python3.9/multiprocessing/spawn.py", line 134, in _check_not_importing_main
    raise RuntimeError('''
RuntimeError: 
        An attempt has been made to start a new process before the
        current process has finished its bootstrapping phase.

        This probably means that you are not using fork to start your
        child processes and you have forgotten to use the proper idiom
        in the main module:

            if __name__ == '__main__':
                freeze_support()
                ...

        The "freeze_support()" line can be omitted if the program
        is not going to be frozen to produce an executable.
2023-04-13 17:46:14,420 - distributed.nanny - ERROR - Failed to start process
Traceback (most recent call last):
  File "/g/data3/hh5/public/apps/miniconda3/envs/analysis3-23.01/lib/python3.9/site-packages/distributed/nanny.py", line 442, in instantiate
    result = await self.process.start()
  File "/g/data3/hh5/public/apps/miniconda3/envs/analysis3-23.01/lib/python3.9/site-packages/distributed/nanny.py", line 711, in start
    await self.process.start()
  File "/g/data3/hh5/public/apps/miniconda3/envs/analysis3-23.01/lib/python3.9/site-packages/distributed/process.py", line 55, in _call_and_set_future
    res = func(*args, **kwargs)
  File "/g/data3/hh5/public/apps/miniconda3/envs/analysis3-23.01/lib/python3.9/site-packages/distributed/process.py", line 215, in _start
    process.start()
  File "/g/data3/hh5/public/apps/miniconda3/envs/analysis3-23.01/lib/python3.9/multiprocessing/process.py", line 121, in start
    self._popen = self._Popen(self)
  File "/g/data3/hh5/public/apps/miniconda3/envs/analysis3-23.01/lib/python3.9/multiprocessing/context.py", line 284, in _Popen
    return Popen(process_obj)
  File "/g/data3/hh5/public/apps/miniconda3/envs/analysis3-23.01/lib/python3.9/multiprocessing/popen_spawn_posix.py", line 32, in __init__
    super().__init__(process_obj)
  File "/g/data3/hh5/public/apps/miniconda3/envs/analysis3-23.01/lib/python3.9/multiprocessing/popen_fork.py", line 19, in __init__
    self._launch(process_obj)
  File "/g/data3/hh5/public/apps/miniconda3/envs/analysis3-23.01/lib/python3.9/multiprocessing/popen_spawn_posix.py", line 42, in _launch
    prep_data = spawn.get_preparation_data(process_obj._name)
  File "/g/data3/hh5/public/apps/miniconda3/envs/analysis3-23.01/lib/python3.9/multiprocessing/spawn.py", line 154, in get_preparation_data
    _check_not_importing_main()
  File "/g/data3/hh5/public/apps/miniconda3/envs/analysis3-23.01/lib/python3.9/multiprocessing/spawn.py", line 134, in _check_not_importing_main
    raise RuntimeError('''
RuntimeError: 
        An attempt has been made to start a new process before the
        current process has finished its bootstrapping phase.

        This probably means that you are not using fork to start your
        child processes and you have forgotten to use the proper idiom
        in the main module:

            if __name__ == '__main__':
                freeze_support()
                ...

        The "freeze_support()" line can be omitted if the program
        is not going to be frozen to produce an executable.
2023-04-13 17:46:14,420 - distributed.nanny - ERROR - Failed to start process
Traceback (most recent call last):
  File "/g/data3/hh5/public/apps/miniconda3/envs/analysis3-23.01/lib/python3.9/site-packages/distributed/nanny.py", line 442, in instantiate
    result = await self.process.start()
  File "/g/data3/hh5/public/apps/miniconda3/envs/analysis3-23.01/lib/python3.9/site-packages/distributed/nanny.py", line 711, in start
    await self.process.start()
  File "/g/data3/hh5/public/apps/miniconda3/envs/analysis3-23.01/lib/python3.9/site-packages/distributed/process.py", line 55, in _call_and_set_future
    res = func(*args, **kwargs)
  File "/g/data3/hh5/public/apps/miniconda3/envs/analysis3-23.01/lib/python3.9/site-packages/distributed/process.py", line 215, in _start
    process.start()
  File "/g/data3/hh5/public/apps/miniconda3/envs/analysis3-23.01/lib/python3.9/multiprocessing/process.py", line 121, in start
    self._popen = self._Popen(self)
  File "/g/data3/hh5/public/apps/miniconda3/envs/analysis3-23.01/lib/python3.9/multiprocessing/context.py", line 284, in _Popen
    return Popen(process_obj)
  File "/g/data3/hh5/public/apps/miniconda3/envs/analysis3-23.01/lib/python3.9/multiprocessing/popen_spawn_posix.py", line 32, in __init__
    super().__init__(process_obj)
  File "/g/data3/hh5/public/apps/miniconda3/envs/analysis3-23.01/lib/python3.9/multiprocessing/popen_fork.py", line 19, in __init__
    self._launch(process_obj)
  File "/g/data3/hh5/public/apps/miniconda3/envs/analysis3-23.01/lib/python3.9/multiprocessing/popen_spawn_posix.py", line 42, in _launch
    prep_data = spawn.get_preparation_data(process_obj._name)
  File "/g/data3/hh5/public/apps/miniconda3/envs/analysis3-23.01/lib/python3.9/multiprocessing/spawn.py", line 154, in get_preparation_data
    _check_not_importing_main()
  File "/g/data3/hh5/public/apps/miniconda3/envs/analysis3-23.01/lib/python3.9/multiprocessing/spawn.py", line 134, in _check_not_importing_main
    raise RuntimeError('''
RuntimeError: 
        An attempt has been made to start a new process before the
        current process has finished its bootstrapping phase.

        This probably means that you are not using fork to start your
        child processes and you have forgotten to use the proper idiom
        in the main module:

            if __name__ == '__main__':
                freeze_support()
                ...

        The "freeze_support()" line can be omitted if the program
        is not going to be frozen to produce an executable.
2023-04-13 17:46:14,421 - distributed.nanny - ERROR - Failed to start process
Traceback (most recent call last):
  File "/g/data3/hh5/public/apps/miniconda3/envs/analysis3-23.01/lib/python3.9/site-packages/distributed/nanny.py", line 442, in instantiate
    result = await self.process.start()
  File "/g/data3/hh5/public/apps/miniconda3/envs/analysis3-23.01/lib/python3.9/site-packages/distributed/nanny.py", line 711, in start
    await self.process.start()
  File "/g/data3/hh5/public/apps/miniconda3/envs/analysis3-23.01/lib/python3.9/site-packages/distributed/process.py", line 55, in _call_and_set_future
    res = func(*args, **kwargs)
  File "/g/data3/hh5/public/apps/miniconda3/envs/analysis3-23.01/lib/python3.9/site-packages/distributed/process.py", line 215, in _start
    process.start()
  File "/g/data3/hh5/public/apps/miniconda3/envs/analysis3-23.01/lib/python3.9/multiprocessing/process.py", line 121, in start
    self._popen = self._Popen(self)
  File "/g/data3/hh5/public/apps/miniconda3/envs/analysis3-23.01/lib/python3.9/multiprocessing/context.py", line 284, in _Popen
    return Popen(process_obj)
  File "/g/data3/hh5/public/apps/miniconda3/envs/analysis3-23.01/lib/python3.9/multiprocessing/popen_spawn_posix.py", line 32, in __init__
    super().__init__(process_obj)
  File "/g/data3/hh5/public/apps/miniconda3/envs/analysis3-23.01/lib/python3.9/multiprocessing/popen_fork.py", line 19, in __init__
    self._launch(process_obj)
  File "/g/data3/hh5/public/apps/miniconda3/envs/analysis3-23.01/lib/python3.9/multiprocessing/popen_spawn_posix.py", line 42, in _launch
    prep_data = spawn.get_preparation_data(process_obj._name)
  File "/g/data3/hh5/public/apps/miniconda3/envs/analysis3-23.01/lib/python3.9/multiprocessing/spawn.py", line 154, in get_preparation_data
    _check_not_importing_main()
  File "/g/data3/hh5/public/apps/miniconda3/envs/analysis3-23.01/lib/python3.9/multiprocessing/spawn.py", line 134, in _check_not_importing_main
    raise RuntimeError('''
RuntimeError: 
        An attempt has been made to start a new process before the
        current process has finished its bootstrapping phase.

        This probably means that you are not using fork to start your
        child processes and you have forgotten to use the proper idiom
        in the main module:

            if __name__ == '__main__':
                freeze_support()
                ...

        The "freeze_support()" line can be omitted if the program
        is not going to be frozen to produce an executable.
2023-04-13 17:46:14,420 - distributed.nanny - ERROR - Failed to start process
Traceback (most recent call last):
  File "/g/data3/hh5/public/apps/miniconda3/envs/analysis3-23.01/lib/python3.9/site-packages/distributed/nanny.py", line 442, in instantiate
    result = await self.process.start()
  File "/g/data3/hh5/public/apps/miniconda3/envs/analysis3-23.01/lib/python3.9/site-packages/distributed/nanny.py", line 711, in start
    await self.process.start()
  File "/g/data3/hh5/public/apps/miniconda3/envs/analysis3-23.01/lib/python3.9/site-packages/distributed/process.py", line 55, in _call_and_set_future
    res = func(*args, **kwargs)
  File "/g/data3/hh5/public/apps/miniconda3/envs/analysis3-23.01/lib/python3.9/site-packages/distributed/process.py", line 215, in _start
    process.start()
  File "/g/data3/hh5/public/apps/miniconda3/envs/analysis3-23.01/lib/python3.9/multiprocessing/process.py", line 121, in start
    self._popen = self._Popen(self)
  File "/g/data3/hh5/public/apps/miniconda3/envs/analysis3-23.01/lib/python3.9/multiprocessing/context.py", line 284, in _Popen
    return Popen(process_obj)
  File "/g/data3/hh5/public/apps/miniconda3/envs/analysis3-23.01/lib/python3.9/multiprocessing/popen_spawn_posix.py", line 32, in __init__
    super().__init__(process_obj)
  File "/g/data3/hh5/public/apps/miniconda3/envs/analysis3-23.01/lib/python3.9/multiprocessing/popen_fork.py", line 19, in __init__
    self._launch(process_obj)
  File "/g/data3/hh5/public/apps/miniconda3/envs/analysis3-23.01/lib/python3.9/multiprocessing/popen_spawn_posix.py", line 42, in _launch
    prep_data = spawn.get_preparation_data(process_obj._name)
  File "/g/data3/hh5/public/apps/miniconda3/envs/analysis3-23.01/lib/python3.9/multiprocessing/spawn.py", line 154, in get_preparation_data
    _check_not_importing_main()
  File "/g/data3/hh5/public/apps/miniconda3/envs/analysis3-23.01/lib/python3.9/multiprocessing/spawn.py", line 134, in _check_not_importing_main
    raise RuntimeError('''
RuntimeError: 
        An attempt has been made to start a new process before the
        current process has finished its bootstrapping phase.

        This probably means that you are not using fork to start your
        child processes and you have forgotten to use the proper idiom
        in the main module:

            if __name__ == '__main__':
                freeze_support()
                ...

        The "freeze_support()" line can be omitted if the program
        is not going to be frozen to produce an executable.
2023-04-13 17:46:14,421 - distributed.nanny - ERROR - Failed to start process
Traceback (most recent call last):
  File "/g/data3/hh5/public/apps/miniconda3/envs/analysis3-23.01/lib/python3.9/site-packages/distributed/nanny.py", line 442, in instantiate
    result = await self.process.start()
  File "/g/data3/hh5/public/apps/miniconda3/envs/analysis3-23.01/lib/python3.9/site-packages/distributed/nanny.py", line 711, in start
    await self.process.start()
  File "/g/data3/hh5/public/apps/miniconda3/envs/analysis3-23.01/lib/python3.9/site-packages/distributed/process.py", line 55, in _call_and_set_future
    res = func(*args, **kwargs)
  File "/g/data3/hh5/public/apps/miniconda3/envs/analysis3-23.01/lib/python3.9/site-packages/distributed/process.py", line 215, in _start
    process.start()
  File "/g/data3/hh5/public/apps/miniconda3/envs/analysis3-23.01/lib/python3.9/multiprocessing/process.py", line 121, in start
    self._popen = self._Popen(self)
  File "/g/data3/hh5/public/apps/miniconda3/envs/analysis3-23.01/lib/python3.9/multiprocessing/context.py", line 284, in _Popen
    return Popen(process_obj)
  File "/g/data3/hh5/public/apps/miniconda3/envs/analysis3-23.01/lib/python3.9/multiprocessing/popen_spawn_posix.py", line 32, in __init__
    super().__init__(process_obj)
  File "/g/data3/hh5/public/apps/miniconda3/envs/analysis3-23.01/lib/python3.9/multiprocessing/popen_fork.py", line 19, in __init__
    self._launch(process_obj)
  File "/g/data3/hh5/public/apps/miniconda3/envs/analysis3-23.01/lib/python3.9/multiprocessing/popen_spawn_posix.py", line 42, in _launch
    prep_data = spawn.get_preparation_data(process_obj._name)
  File "/g/data3/hh5/public/apps/miniconda3/envs/analysis3-23.01/lib/python3.9/multiprocessing/spawn.py", line 154, in get_preparation_data
    _check_not_importing_main()
  File "/g/data3/hh5/public/apps/miniconda3/envs/analysis3-23.01/lib/python3.9/multiprocessing/spawn.py", line 134, in _check_not_importing_main
    raise RuntimeError('''
RuntimeError: 
        An attempt has been made to start a new process before the
        current process has finished its bootstrapping phase.

        This probably means that you are not using fork to start your
        child processes and you have forgotten to use the proper idiom
        in the main module:

            if __name__ == '__main__':
                freeze_support()
                ...

        The "freeze_support()" line can be omitted if the program
        is not going to be frozen to produce an executable.
2023-04-13 17:46:14,421 - distributed.nanny - ERROR - Failed to start process
Traceback (most recent call last):
  File "/g/data3/hh5/public/apps/miniconda3/envs/analysis3-23.01/lib/python3.9/site-packages/distributed/nanny.py", line 442, in instantiate
    result = await self.process.start()
  File "/g/data3/hh5/public/apps/miniconda3/envs/analysis3-23.01/lib/python3.9/site-packages/distributed/nanny.py", line 711, in start
    await self.process.start()
  File "/g/data3/hh5/public/apps/miniconda3/envs/analysis3-23.01/lib/python3.9/site-packages/distributed/process.py", line 55, in _call_and_set_future
    res = func(*args, **kwargs)
  File "/g/data3/hh5/public/apps/miniconda3/envs/analysis3-23.01/lib/python3.9/site-packages/distributed/process.py", line 215, in _start
    process.start()
  File "/g/data3/hh5/public/apps/miniconda3/envs/analysis3-23.01/lib/python3.9/multiprocessing/process.py", line 121, in start
    self._popen = self._Popen(self)
  File "/g/data3/hh5/public/apps/miniconda3/envs/analysis3-23.01/lib/python3.9/multiprocessing/context.py", line 284, in _Popen
    return Popen(process_obj)
  File "/g/data3/hh5/public/apps/miniconda3/envs/analysis3-23.01/lib/python3.9/multiprocessing/popen_spawn_posix.py", line 32, in __init__
    super().__init__(process_obj)
  File "/g/data3/hh5/public/apps/miniconda3/envs/analysis3-23.01/lib/python3.9/multiprocessing/popen_fork.py", line 19, in __init__
    self._launch(process_obj)
  File "/g/data3/hh5/public/apps/miniconda3/envs/analysis3-23.01/lib/python3.9/multiprocessing/popen_spawn_posix.py", line 42, in _launch
    prep_data = spawn.get_preparation_data(process_obj._name)
  File "/g/data3/hh5/public/apps/miniconda3/envs/analysis3-23.01/lib/python3.9/multiprocessing/spawn.py", line 154, in get_preparation_data
    _check_not_importing_main()
  File "/g/data3/hh5/public/apps/miniconda3/envs/analysis3-23.01/lib/python3.9/multiprocessing/spawn.py", line 134, in _check_not_importing_main
    raise RuntimeError('''
RuntimeError: 
        An attempt has been made to start a new process before the
        current process has finished its bootstrapping phase.

        This probably means that you are not using fork to start your
        child processes and you have forgotten to use the proper idiom
        in the main module:

            if __name__ == '__main__':
                freeze_support()
                ...

        The "freeze_support()" line can be omitted if the program
        is not going to be frozen to produce an executable.
2023-04-13 17:46:14,421 - distributed.nanny - ERROR - Failed to start process
Traceback (most recent call last):
  File "/g/data3/hh5/public/apps/miniconda3/envs/analysis3-23.01/lib/python3.9/site-packages/distributed/nanny.py", line 442, in instantiate
    result = await self.process.start()
  File "/g/data3/hh5/public/apps/miniconda3/envs/analysis3-23.01/lib/python3.9/site-packages/distributed/nanny.py", line 711, in start
    await self.process.start()
  File "/g/data3/hh5/public/apps/miniconda3/envs/analysis3-23.01/lib/python3.9/site-packages/distributed/process.py", line 55, in _call_and_set_future
    res = func(*args, **kwargs)
  File "/g/data3/hh5/public/apps/miniconda3/envs/analysis3-23.01/lib/python3.9/site-packages/distributed/process.py", line 215, in _start
    process.start()
  File "/g/data3/hh5/public/apps/miniconda3/envs/analysis3-23.01/lib/python3.9/multiprocessing/process.py", line 121, in start
    self._popen = self._Popen(self)
  File "/g/data3/hh5/public/apps/miniconda3/envs/analysis3-23.01/lib/python3.9/multiprocessing/context.py", line 284, in _Popen
    return Popen(process_obj)
  File "/g/data3/hh5/public/apps/miniconda3/envs/analysis3-23.01/lib/python3.9/multiprocessing/popen_spawn_posix.py", line 32, in __init__
    super().__init__(process_obj)
  File "/g/data3/hh5/public/apps/miniconda3/envs/analysis3-23.01/lib/python3.9/multiprocessing/popen_fork.py", line 19, in __init__
    self._launch(process_obj)
  File "/g/data3/hh5/public/apps/miniconda3/envs/analysis3-23.01/lib/python3.9/multiprocessing/popen_spawn_posix.py", line 42, in _launch
    prep_data = spawn.get_preparation_data(process_obj._name)
  File "/g/data3/hh5/public/apps/miniconda3/envs/analysis3-23.01/lib/python3.9/multiprocessing/spawn.py", line 154, in get_preparation_data
    _check_not_importing_main()
  File "/g/data3/hh5/public/apps/miniconda3/envs/analysis3-23.01/lib/python3.9/multiprocessing/spawn.py", line 134, in _check_not_importing_main
    raise RuntimeError('''
RuntimeError: 
        An attempt has been made to start a new process before the
        current process has finished its bootstrapping phase.

        This probably means that you are not using fork to start your
        child processes and you have forgotten to use the proper idiom
        in the main module:

            if __name__ == '__main__':
                freeze_support()
                ...

        The "freeze_support()" line can be omitted if the program
        is not going to be frozen to produce an executable.
2023-04-13 17:46:14,420 - distributed.nanny - ERROR - Failed to start process
Traceback (most recent call last):
  File "/g/data3/hh5/public/apps/miniconda3/envs/analysis3-23.01/lib/python3.9/site-packages/distributed/nanny.py", line 442, in instantiate
    result = await self.process.start()
  File "/g/data3/hh5/public/apps/miniconda3/envs/analysis3-23.01/lib/python3.9/site-packages/distributed/nanny.py", line 711, in start
    await self.process.start()
  File "/g/data3/hh5/public/apps/miniconda3/envs/analysis3-23.01/lib/python3.9/site-packages/distributed/process.py", line 55, in _call_and_set_future
    res = func(*args, **kwargs)
  File "/g/data3/hh5/public/apps/miniconda3/envs/analysis3-23.01/lib/python3.9/site-packages/distributed/process.py", line 215, in _start
    process.start()
  File "/g/data3/hh5/public/apps/miniconda3/envs/analysis3-23.01/lib/python3.9/multiprocessing/process.py", line 121, in start
    self._popen = self._Popen(self)
  File "/g/data3/hh5/public/apps/miniconda3/envs/analysis3-23.01/lib/python3.9/multiprocessing/context.py", line 284, in _Popen
    return Popen(process_obj)
  File "/g/data3/hh5/public/apps/miniconda3/envs/analysis3-23.01/lib/python3.9/multiprocessing/popen_spawn_posix.py", line 32, in __init__
    super().__init__(process_obj)
  File "/g/data3/hh5/public/apps/miniconda3/envs/analysis3-23.01/lib/python3.9/multiprocessing/popen_fork.py", line 19, in __init__
    self._launch(process_obj)
  File "/g/data3/hh5/public/apps/miniconda3/envs/analysis3-23.01/lib/python3.9/multiprocessing/popen_spawn_posix.py", line 42, in _launch
    prep_data = spawn.get_preparation_data(process_obj._name)
  File "/g/data3/hh5/public/apps/miniconda3/envs/analysis3-23.01/lib/python3.9/multiprocessing/spawn.py", line 154, in get_preparation_data
    _check_not_importing_main()
  File "/g/data3/hh5/public/apps/miniconda3/envs/analysis3-23.01/lib/python3.9/multiprocessing/spawn.py", line 134, in _check_not_importing_main
    raise RuntimeError('''
RuntimeError: 
        An attempt has been made to start a new process before the
        current process has finished its bootstrapping phase.

        This probably means that you are not using fork to start your
        child processes and you have forgotten to use the proper idiom
        in the main module:

            if __name__ == '__main__':
                freeze_support()
                ...

        The "freeze_support()" line can be omitted if the program
        is not going to be frozen to produce an executable.
2023-04-13 17:46:14,421 - distributed.nanny - ERROR - Failed to start process
Traceback (most recent call last):
  File "/g/data3/hh5/public/apps/miniconda3/envs/analysis3-23.01/lib/python3.9/site-packages/distributed/nanny.py", line 442, in instantiate
    result = await self.process.start()
  File "/g/data3/hh5/public/apps/miniconda3/envs/analysis3-23.01/lib/python3.9/site-packages/distributed/nanny.py", line 711, in start
    await self.process.start()
  File "/g/data3/hh5/public/apps/miniconda3/envs/analysis3-23.01/lib/python3.9/site-packages/distributed/process.py", line 55, in _call_and_set_future
    res = func(*args, **kwargs)
  File "/g/data3/hh5/public/apps/miniconda3/envs/analysis3-23.01/lib/python3.9/site-packages/distributed/process.py", line 215, in _start
    process.start()
  File "/g/data3/hh5/public/apps/miniconda3/envs/analysis3-23.01/lib/python3.9/multiprocessing/process.py", line 121, in start
    self._popen = self._Popen(self)
  File "/g/data3/hh5/public/apps/miniconda3/envs/analysis3-23.01/lib/python3.9/multiprocessing/context.py", line 284, in _Popen
    return Popen(process_obj)
  File "/g/data3/hh5/public/apps/miniconda3/envs/analysis3-23.01/lib/python3.9/multiprocessing/popen_spawn_posix.py", line 32, in __init__
    super().__init__(process_obj)
  File "/g/data3/hh5/public/apps/miniconda3/envs/analysis3-23.01/lib/python3.9/multiprocessing/popen_fork.py", line 19, in __init__
    self._launch(process_obj)
  File "/g/data3/hh5/public/apps/miniconda3/envs/analysis3-23.01/lib/python3.9/multiprocessing/popen_spawn_posix.py", line 42, in _launch
    prep_data = spawn.get_preparation_data(process_obj._name)
  File "/g/data3/hh5/public/apps/miniconda3/envs/analysis3-23.01/lib/python3.9/multiprocessing/spawn.py", line 154, in get_preparation_data
    _check_not_importing_main()
  File "/g/data3/hh5/public/apps/miniconda3/envs/analysis3-23.01/lib/python3.9/multiprocessing/spawn.py", line 134, in _check_not_importing_main
    raise RuntimeError('''
RuntimeError: 
        An attempt has been made to start a new process before the
        current process has finished its bootstrapping phase.

        This probably means that you are not using fork to start your
        child processes and you have forgotten to use the proper idiom
        in the main module:

            if __name__ == '__main__':
                freeze_support()
                ...

        The "freeze_support()" line can be omitted if the program
        is not going to be frozen to produce an executable.
2023-04-13 17:46:14,421 - distributed.nanny - ERROR - Failed to start process
Traceback (most recent call last):
  File "/g/data3/hh5/public/apps/miniconda3/envs/analysis3-23.01/lib/python3.9/site-packages/distributed/nanny.py", line 442, in instantiate
    result = await self.process.start()
  File "/g/data3/hh5/public/apps/miniconda3/envs/analysis3-23.01/lib/python3.9/site-packages/distributed/nanny.py", line 711, in start
    await self.process.start()
  File "/g/data3/hh5/public/apps/miniconda3/envs/analysis3-23.01/lib/python3.9/site-packages/distributed/process.py", line 55, in _call_and_set_future
    res = func(*args, **kwargs)
  File "/g/data3/hh5/public/apps/miniconda3/envs/analysis3-23.01/lib/python3.9/site-packages/distributed/process.py", line 215, in _start
    process.start()
  File "/g/data3/hh5/public/apps/miniconda3/envs/analysis3-23.01/lib/python3.9/multiprocessing/process.py", line 121, in start
    self._popen = self._Popen(self)
  File "/g/data3/hh5/public/apps/miniconda3/envs/analysis3-23.01/lib/python3.9/multiprocessing/context.py", line 284, in _Popen
    return Popen(process_obj)
  File "/g/data3/hh5/public/apps/miniconda3/envs/analysis3-23.01/lib/python3.9/multiprocessing/popen_spawn_posix.py", line 32, in __init__
    super().__init__(process_obj)
  File "/g/data3/hh5/public/apps/miniconda3/envs/analysis3-23.01/lib/python3.9/multiprocessing/popen_fork.py", line 19, in __init__
    self._launch(process_obj)
  File "/g/data3/hh5/public/apps/miniconda3/envs/analysis3-23.01/lib/python3.9/multiprocessing/popen_spawn_posix.py", line 42, in _launch
    prep_data = spawn.get_preparation_data(process_obj._name)
  File "/g/data3/hh5/public/apps/miniconda3/envs/analysis3-23.01/lib/python3.9/multiprocessing/spawn.py", line 154, in get_preparation_data
    _check_not_importing_main()
  File "/g/data3/hh5/public/apps/miniconda3/envs/analysis3-23.01/lib/python3.9/multiprocessing/spawn.py", line 134, in _check_not_importing_main
    raise RuntimeError('''
RuntimeError: 
        An attempt has been made to start a new process before the
        current process has finished its bootstrapping phase.

        This probably means that you are not using fork to start your
        child processes and you have forgotten to use the proper idiom
        in the main module:

            if __name__ == '__main__':
                freeze_support()
                ...

        The "freeze_support()" line can be omitted if the program
        is not going to be frozen to produce an executable.
2023-04-13 17:46:14,421 - distributed.nanny - ERROR - Failed to start process
Traceback (most recent call last):
  File "/g/data3/hh5/public/apps/miniconda3/envs/analysis3-23.01/lib/python3.9/site-packages/distributed/nanny.py", line 442, in instantiate
    result = await self.process.start()
  File "/g/data3/hh5/public/apps/miniconda3/envs/analysis3-23.01/lib/python3.9/site-packages/distributed/nanny.py", line 711, in start
    await self.process.start()
  File "/g/data3/hh5/public/apps/miniconda3/envs/analysis3-23.01/lib/python3.9/site-packages/distributed/process.py", line 55, in _call_and_set_future
    res = func(*args, **kwargs)
  File "/g/data3/hh5/public/apps/miniconda3/envs/analysis3-23.01/lib/python3.9/site-packages/distributed/process.py", line 215, in _start
    process.start()
  File "/g/data3/hh5/public/apps/miniconda3/envs/analysis3-23.01/lib/python3.9/multiprocessing/process.py", line 121, in start
    self._popen = self._Popen(self)
  File "/g/data3/hh5/public/apps/miniconda3/envs/analysis3-23.01/lib/python3.9/multiprocessing/context.py", line 284, in _Popen
    return Popen(process_obj)
  File "/g/data3/hh5/public/apps/miniconda3/envs/analysis3-23.01/lib/python3.9/multiprocessing/popen_spawn_posix.py", line 32, in __init__
    super().__init__(process_obj)
  File "/g/data3/hh5/public/apps/miniconda3/envs/analysis3-23.01/lib/python3.9/multiprocessing/popen_fork.py", line 19, in __init__
    self._launch(process_obj)
  File "/g/data3/hh5/public/apps/miniconda3/envs/analysis3-23.01/lib/python3.9/multiprocessing/popen_spawn_posix.py", line 42, in _launch
    prep_data = spawn.get_preparation_data(process_obj._name)
  File "/g/data3/hh5/public/apps/miniconda3/envs/analysis3-23.01/lib/python3.9/multiprocessing/spawn.py", line 154, in get_preparation_data
    _check_not_importing_main()
  File "/g/data3/hh5/public/apps/miniconda3/envs/analysis3-23.01/lib/python3.9/multiprocessing/spawn.py", line 134, in _check_not_importing_main
    raise RuntimeError('''
RuntimeError: 
        An attempt has been made to start a new process before the
        current process has finished its bootstrapping phase.

        This probably means that you are not using fork to start your
        child processes and you have forgotten to use the proper idiom
        in the main module:

            if __name__ == '__main__':
                freeze_support()
                ...

        The "freeze_support()" line can be omitted if the program
        is not going to be frozen to produce an executable.
2023-04-13 17:46:14,421 - distributed.nanny - ERROR - Failed to start process
Traceback (most recent call last):
  File "/g/data3/hh5/public/apps/miniconda3/envs/analysis3-23.01/lib/python3.9/site-packages/distributed/nanny.py", line 442, in instantiate
    result = await self.process.start()
  File "/g/data3/hh5/public/apps/miniconda3/envs/analysis3-23.01/lib/python3.9/site-packages/distributed/nanny.py", line 711, in start
    await self.process.start()
  File "/g/data3/hh5/public/apps/miniconda3/envs/analysis3-23.01/lib/python3.9/site-packages/distributed/process.py", line 55, in _call_and_set_future
    res = func(*args, **kwargs)
  File "/g/data3/hh5/public/apps/miniconda3/envs/analysis3-23.01/lib/python3.9/site-packages/distributed/process.py", line 215, in _start
    process.start()
  File "/g/data3/hh5/public/apps/miniconda3/envs/analysis3-23.01/lib/python3.9/multiprocessing/process.py", line 121, in start
    self._popen = self._Popen(self)
  File "/g/data3/hh5/public/apps/miniconda3/envs/analysis3-23.01/lib/python3.9/multiprocessing/context.py", line 284, in _Popen
    return Popen(process_obj)
  File "/g/data3/hh5/public/apps/miniconda3/envs/analysis3-23.01/lib/python3.9/multiprocessing/popen_spawn_posix.py", line 32, in __init__
    super().__init__(process_obj)
  File "/g/data3/hh5/public/apps/miniconda3/envs/analysis3-23.01/lib/python3.9/multiprocessing/popen_fork.py", line 19, in __init__
    self._launch(process_obj)
  File "/g/data3/hh5/public/apps/miniconda3/envs/analysis3-23.01/lib/python3.9/multiprocessing/popen_spawn_posix.py", line 42, in _launch
    prep_data = spawn.get_preparation_data(process_obj._name)
  File "/g/data3/hh5/public/apps/miniconda3/envs/analysis3-23.01/lib/python3.9/multiprocessing/spawn.py", line 154, in get_preparation_data
    _check_not_importing_main()
  File "/g/data3/hh5/public/apps/miniconda3/envs/analysis3-23.01/lib/python3.9/multiprocessing/spawn.py", line 134, in _check_not_importing_main
    raise RuntimeError('''
RuntimeError: 
        An attempt has been made to start a new process before the
        current process has finished its bootstrapping phase.

        This probably means that you are not using fork to start your
        child processes and you have forgotten to use the proper idiom
        in the main module:

            if __name__ == '__main__':
                freeze_support()
                ...

        The "freeze_support()" line can be omitted if the program
        is not going to be frozen to produce an executable.
2023-04-13 17:46:14,421 - distributed.nanny - ERROR - Failed to start process
Traceback (most recent call last):
  File "/g/data3/hh5/public/apps/miniconda3/envs/analysis3-23.01/lib/python3.9/site-packages/distributed/nanny.py", line 442, in instantiate
    result = await self.process.start()
  File "/g/data3/hh5/public/apps/miniconda3/envs/analysis3-23.01/lib/python3.9/site-packages/distributed/nanny.py", line 711, in start
    await self.process.start()
  File "/g/data3/hh5/public/apps/miniconda3/envs/analysis3-23.01/lib/python3.9/site-packages/distributed/process.py", line 55, in _call_and_set_future
    res = func(*args, **kwargs)
  File "/g/data3/hh5/public/apps/miniconda3/envs/analysis3-23.01/lib/python3.9/site-packages/distributed/process.py", line 215, in _start
    process.start()
  File "/g/data3/hh5/public/apps/miniconda3/envs/analysis3-23.01/lib/python3.9/multiprocessing/process.py", line 121, in start
    self._popen = self._Popen(self)
  File "/g/data3/hh5/public/apps/miniconda3/envs/analysis3-23.01/lib/python3.9/multiprocessing/context.py", line 284, in _Popen
    return Popen(process_obj)
  File "/g/data3/hh5/public/apps/miniconda3/envs/analysis3-23.01/lib/python3.9/multiprocessing/popen_spawn_posix.py", line 32, in __init__
    super().__init__(process_obj)
  File "/g/data3/hh5/public/apps/miniconda3/envs/analysis3-23.01/lib/python3.9/multiprocessing/popen_fork.py", line 19, in __init__
    self._launch(process_obj)
  File "/g/data3/hh5/public/apps/miniconda3/envs/analysis3-23.01/lib/python3.9/multiprocessing/popen_spawn_posix.py", line 42, in _launch
    prep_data = spawn.get_preparation_data(process_obj._name)
  File "/g/data3/hh5/public/apps/miniconda3/envs/analysis3-23.01/lib/python3.9/multiprocessing/spawn.py", line 154, in get_preparation_data
    _check_not_importing_main()
  File "/g/data3/hh5/public/apps/miniconda3/envs/analysis3-23.01/lib/python3.9/multiprocessing/spawn.py", line 134, in _check_not_importing_main
    raise RuntimeError('''
RuntimeError: 
        An attempt has been made to start a new process before the
        current process has finished its bootstrapping phase.

        This probably means that you are not using fork to start your
        child processes and you have forgotten to use the proper idiom
        in the main module:

            if __name__ == '__main__':
                freeze_support()
                ...

        The "freeze_support()" line can be omitted if the program
        is not going to be frozen to produce an executable.
2023-04-13 17:46:14,421 - distributed.nanny - ERROR - Failed to start process
Traceback (most recent call last):
  File "/g/data3/hh5/public/apps/miniconda3/envs/analysis3-23.01/lib/python3.9/site-packages/distributed/nanny.py", line 442, in instantiate
    result = await self.process.start()
  File "/g/data3/hh5/public/apps/miniconda3/envs/analysis3-23.01/lib/python3.9/site-packages/distributed/nanny.py", line 711, in start
    await self.process.start()
  File "/g/data3/hh5/public/apps/miniconda3/envs/analysis3-23.01/lib/python3.9/site-packages/distributed/process.py", line 55, in _call_and_set_future
    res = func(*args, **kwargs)
  File "/g/data3/hh5/public/apps/miniconda3/envs/analysis3-23.01/lib/python3.9/site-packages/distributed/process.py", line 215, in _start
    process.start()
  File "/g/data3/hh5/public/apps/miniconda3/envs/analysis3-23.01/lib/python3.9/multiprocessing/process.py", line 121, in start
    self._popen = self._Popen(self)
  File "/g/data3/hh5/public/apps/miniconda3/envs/analysis3-23.01/lib/python3.9/multiprocessing/context.py", line 284, in _Popen
    return Popen(process_obj)
  File "/g/data3/hh5/public/apps/miniconda3/envs/analysis3-23.01/lib/python3.9/multiprocessing/popen_spawn_posix.py", line 32, in __init__
    super().__init__(process_obj)
  File "/g/data3/hh5/public/apps/miniconda3/envs/analysis3-23.01/lib/python3.9/multiprocessing/popen_fork.py", line 19, in __init__
    self._launch(process_obj)
  File "/g/data3/hh5/public/apps/miniconda3/envs/analysis3-23.01/lib/python3.9/multiprocessing/popen_spawn_posix.py", line 42, in _launch
    prep_data = spawn.get_preparation_data(process_obj._name)
  File "/g/data3/hh5/public/apps/miniconda3/envs/analysis3-23.01/lib/python3.9/multiprocessing/spawn.py", line 154, in get_preparation_data
    _check_not_importing_main()
  File "/g/data3/hh5/public/apps/miniconda3/envs/analysis3-23.01/lib/python3.9/multiprocessing/spawn.py", line 134, in _check_not_importing_main
    raise RuntimeError('''
RuntimeError: 
        An attempt has been made to start a new process before the
        current process has finished its bootstrapping phase.

        This probably means that you are not using fork to start your
        child processes and you have forgotten to use the proper idiom
        in the main module:

            if __name__ == '__main__':
                freeze_support()
                ...

        The "freeze_support()" line can be omitted if the program
        is not going to be frozen to produce an executable.
2023-04-13 17:46:14,422 - distributed.nanny - ERROR - Failed to start process
Traceback (most recent call last):
  File "/g/data3/hh5/public/apps/miniconda3/envs/analysis3-23.01/lib/python3.9/site-packages/distributed/nanny.py", line 442, in instantiate
    result = await self.process.start()
  File "/g/data3/hh5/public/apps/miniconda3/envs/analysis3-23.01/lib/python3.9/site-packages/distributed/nanny.py", line 711, in start
    await self.process.start()
  File "/g/data3/hh5/public/apps/miniconda3/envs/analysis3-23.01/lib/python3.9/site-packages/distributed/process.py", line 55, in _call_and_set_future
    res = func(*args, **kwargs)
  File "/g/data3/hh5/public/apps/miniconda3/envs/analysis3-23.01/lib/python3.9/site-packages/distributed/process.py", line 215, in _start
    process.start()
  File "/g/data3/hh5/public/apps/miniconda3/envs/analysis3-23.01/lib/python3.9/multiprocessing/process.py", line 121, in start
    self._popen = self._Popen(self)
  File "/g/data3/hh5/public/apps/miniconda3/envs/analysis3-23.01/lib/python3.9/multiprocessing/context.py", line 284, in _Popen
    return Popen(process_obj)
  File "/g/data3/hh5/public/apps/miniconda3/envs/analysis3-23.01/lib/python3.9/multiprocessing/popen_spawn_posix.py", line 32, in __init__
    super().__init__(process_obj)
  File "/g/data3/hh5/public/apps/miniconda3/envs/analysis3-23.01/lib/python3.9/multiprocessing/popen_fork.py", line 19, in __init__
    self._launch(process_obj)
  File "/g/data3/hh5/public/apps/miniconda3/envs/analysis3-23.01/lib/python3.9/multiprocessing/popen_spawn_posix.py", line 42, in _launch
    prep_data = spawn.get_preparation_data(process_obj._name)
  File "/g/data3/hh5/public/apps/miniconda3/envs/analysis3-23.01/lib/python3.9/multiprocessing/spawn.py", line 154, in get_preparation_data
    _check_not_importing_main()
  File "/g/data3/hh5/public/apps/miniconda3/envs/analysis3-23.01/lib/python3.9/multiprocessing/spawn.py", line 134, in _check_not_importing_main
    raise RuntimeError('''
RuntimeError: 
        An attempt has been made to start a new process before the
        current process has finished its bootstrapping phase.

        This probably means that you are not using fork to start your
        child processes and you have forgotten to use the proper idiom
        in the main module:

            if __name__ == '__main__':
                freeze_support()
                ...

        The "freeze_support()" line can be omitted if the program
        is not going to be frozen to produce an executable.
2023-04-13 17:46:14,422 - distributed.nanny - ERROR - Failed to start process
Traceback (most recent call last):
  File "/g/data3/hh5/public/apps/miniconda3/envs/analysis3-23.01/lib/python3.9/site-packages/distributed/nanny.py", line 442, in instantiate
    result = await self.process.start()
  File "/g/data3/hh5/public/apps/miniconda3/envs/analysis3-23.01/lib/python3.9/site-packages/distributed/nanny.py", line 711, in start
    await self.process.start()
  File "/g/data3/hh5/public/apps/miniconda3/envs/analysis3-23.01/lib/python3.9/site-packages/distributed/process.py", line 55, in _call_and_set_future
    res = func(*args, **kwargs)
  File "/g/data3/hh5/public/apps/miniconda3/envs/analysis3-23.01/lib/python3.9/site-packages/distributed/process.py", line 215, in _start
    process.start()
  File "/g/data3/hh5/public/apps/miniconda3/envs/analysis3-23.01/lib/python3.9/multiprocessing/process.py", line 121, in start
    self._popen = self._Popen(self)
  File "/g/data3/hh5/public/apps/miniconda3/envs/analysis3-23.01/lib/python3.9/multiprocessing/context.py", line 284, in _Popen
    return Popen(process_obj)
  File "/g/data3/hh5/public/apps/miniconda3/envs/analysis3-23.01/lib/python3.9/multiprocessing/popen_spawn_posix.py", line 32, in __init__
    super().__init__(process_obj)
  File "/g/data3/hh5/public/apps/miniconda3/envs/analysis3-23.01/lib/python3.9/multiprocessing/popen_fork.py", line 19, in __init__
    self._launch(process_obj)
  File "/g/data3/hh5/public/apps/miniconda3/envs/analysis3-23.01/lib/python3.9/multiprocessing/popen_spawn_posix.py", line 42, in _launch
    prep_data = spawn.get_preparation_data(process_obj._name)
  File "/g/data3/hh5/public/apps/miniconda3/envs/analysis3-23.01/lib/python3.9/multiprocessing/spawn.py", line 154, in get_preparation_data
    _check_not_importing_main()
  File "/g/data3/hh5/public/apps/miniconda3/envs/analysis3-23.01/lib/python3.9/multiprocessing/spawn.py", line 134, in _check_not_importing_main
    raise RuntimeError('''
RuntimeError: 
        An attempt has been made to start a new process before the
        current process has finished its bootstrapping phase.

        This probably means that you are not using fork to start your
        child processes and you have forgotten to use the proper idiom
        in the main module:

            if __name__ == '__main__':
                freeze_support()
                ...

        The "freeze_support()" line can be omitted if the program
        is not going to be frozen to produce an executable.
2023-04-13 17:46:14,423 - distributed.nanny - ERROR - Failed to start process
Traceback (most recent call last):
  File "/g/data3/hh5/public/apps/miniconda3/envs/analysis3-23.01/lib/python3.9/site-packages/distributed/nanny.py", line 442, in instantiate
    result = await self.process.start()
  File "/g/data3/hh5/public/apps/miniconda3/envs/analysis3-23.01/lib/python3.9/site-packages/distributed/nanny.py", line 711, in start
    await self.process.start()
  File "/g/data3/hh5/public/apps/miniconda3/envs/analysis3-23.01/lib/python3.9/site-packages/distributed/process.py", line 55, in _call_and_set_future
    res = func(*args, **kwargs)
  File "/g/data3/hh5/public/apps/miniconda3/envs/analysis3-23.01/lib/python3.9/site-packages/distributed/process.py", line 215, in _start
    process.start()
  File "/g/data3/hh5/public/apps/miniconda3/envs/analysis3-23.01/lib/python3.9/multiprocessing/process.py", line 121, in start
    self._popen = self._Popen(self)
  File "/g/data3/hh5/public/apps/miniconda3/envs/analysis3-23.01/lib/python3.9/multiprocessing/context.py", line 284, in _Popen
    return Popen(process_obj)
  File "/g/data3/hh5/public/apps/miniconda3/envs/analysis3-23.01/lib/python3.9/multiprocessing/popen_spawn_posix.py", line 32, in __init__
    super().__init__(process_obj)
  File "/g/data3/hh5/public/apps/miniconda3/envs/analysis3-23.01/lib/python3.9/multiprocessing/popen_fork.py", line 19, in __init__
    self._launch(process_obj)
  File "/g/data3/hh5/public/apps/miniconda3/envs/analysis3-23.01/lib/python3.9/multiprocessing/popen_spawn_posix.py", line 42, in _launch
    prep_data = spawn.get_preparation_data(process_obj._name)
  File "/g/data3/hh5/public/apps/miniconda3/envs/analysis3-23.01/lib/python3.9/multiprocessing/spawn.py", line 154, in get_preparation_data
    _check_not_importing_main()
  File "/g/data3/hh5/public/apps/miniconda3/envs/analysis3-23.01/lib/python3.9/multiprocessing/spawn.py", line 134, in _check_not_importing_main
    raise RuntimeError('''
RuntimeError: 
        An attempt has been made to start a new process before the
        current process has finished its bootstrapping phase.

        This probably means that you are not using fork to start your
        child processes and you have forgotten to use the proper idiom
        in the main module:

            if __name__ == '__main__':
                freeze_support()
                ...

        The "freeze_support()" line can be omitted if the program
        is not going to be frozen to produce an executable.
2023-04-13 17:46:14,423 - distributed.nanny - ERROR - Failed to start process
Traceback (most recent call last):
  File "/g/data3/hh5/public/apps/miniconda3/envs/analysis3-23.01/lib/python3.9/site-packages/distributed/nanny.py", line 442, in instantiate
    result = await self.process.start()
  File "/g/data3/hh5/public/apps/miniconda3/envs/analysis3-23.01/lib/python3.9/site-packages/distributed/nanny.py", line 711, in start
    await self.process.start()
  File "/g/data3/hh5/public/apps/miniconda3/envs/analysis3-23.01/lib/python3.9/site-packages/distributed/process.py", line 55, in _call_and_set_future
    res = func(*args, **kwargs)
  File "/g/data3/hh5/public/apps/miniconda3/envs/analysis3-23.01/lib/python3.9/site-packages/distributed/process.py", line 215, in _start
    process.start()
  File "/g/data3/hh5/public/apps/miniconda3/envs/analysis3-23.01/lib/python3.9/multiprocessing/process.py", line 121, in start
    self._popen = self._Popen(self)
  File "/g/data3/hh5/public/apps/miniconda3/envs/analysis3-23.01/lib/python3.9/multiprocessing/context.py", line 284, in _Popen
    return Popen(process_obj)
  File "/g/data3/hh5/public/apps/miniconda3/envs/analysis3-23.01/lib/python3.9/multiprocessing/popen_spawn_posix.py", line 32, in __init__
    super().__init__(process_obj)
  File "/g/data3/hh5/public/apps/miniconda3/envs/analysis3-23.01/lib/python3.9/multiprocessing/popen_fork.py", line 19, in __init__
    self._launch(process_obj)
  File "/g/data3/hh5/public/apps/miniconda3/envs/analysis3-23.01/lib/python3.9/multiprocessing/popen_spawn_posix.py", line 42, in _launch
    prep_data = spawn.get_preparation_data(process_obj._name)
  File "/g/data3/hh5/public/apps/miniconda3/envs/analysis3-23.01/lib/python3.9/multiprocessing/spawn.py", line 154, in get_preparation_data
    _check_not_importing_main()
  File "/g/data3/hh5/public/apps/miniconda3/envs/analysis3-23.01/lib/python3.9/multiprocessing/spawn.py", line 134, in _check_not_importing_main
    raise RuntimeError('''
RuntimeError: 
        An attempt has been made to start a new process before the
        current process has finished its bootstrapping phase.

        This probably means that you are not using fork to start your
        child processes and you have forgotten to use the proper idiom
        in the main module:

            if __name__ == '__main__':
                freeze_support()
                ...

        The "freeze_support()" line can be omitted if the program
        is not going to be frozen to produce an executable.
2023-04-13 17:46:14,424 - distributed.nanny - ERROR - Failed to start process
Traceback (most recent call last):
  File "/g/data3/hh5/public/apps/miniconda3/envs/analysis3-23.01/lib/python3.9/site-packages/distributed/nanny.py", line 442, in instantiate
    result = await self.process.start()
  File "/g/data3/hh5/public/apps/miniconda3/envs/analysis3-23.01/lib/python3.9/site-packages/distributed/nanny.py", line 711, in start
    await self.process.start()
  File "/g/data3/hh5/public/apps/miniconda3/envs/analysis3-23.01/lib/python3.9/site-packages/distributed/process.py", line 55, in _call_and_set_future
    res = func(*args, **kwargs)
  File "/g/data3/hh5/public/apps/miniconda3/envs/analysis3-23.01/lib/python3.9/site-packages/distributed/process.py", line 215, in _start
    process.start()
  File "/g/data3/hh5/public/apps/miniconda3/envs/analysis3-23.01/lib/python3.9/multiprocessing/process.py", line 121, in start
    self._popen = self._Popen(self)
  File "/g/data3/hh5/public/apps/miniconda3/envs/analysis3-23.01/lib/python3.9/multiprocessing/context.py", line 284, in _Popen
    return Popen(process_obj)
  File "/g/data3/hh5/public/apps/miniconda3/envs/analysis3-23.01/lib/python3.9/multiprocessing/popen_spawn_posix.py", line 32, in __init__
    super().__init__(process_obj)
  File "/g/data3/hh5/public/apps/miniconda3/envs/analysis3-23.01/lib/python3.9/multiprocessing/popen_fork.py", line 19, in __init__
    self._launch(process_obj)
  File "/g/data3/hh5/public/apps/miniconda3/envs/analysis3-23.01/lib/python3.9/multiprocessing/popen_spawn_posix.py", line 42, in _launch
    prep_data = spawn.get_preparation_data(process_obj._name)
  File "/g/data3/hh5/public/apps/miniconda3/envs/analysis3-23.01/lib/python3.9/multiprocessing/spawn.py", line 154, in get_preparation_data
    _check_not_importing_main()
  File "/g/data3/hh5/public/apps/miniconda3/envs/analysis3-23.01/lib/python3.9/multiprocessing/spawn.py", line 134, in _check_not_importing_main
    raise RuntimeError('''
RuntimeError: 
        An attempt has been made to start a new process before the
        current process has finished its bootstrapping phase.

        This probably means that you are not using fork to start your
        child processes and you have forgotten to use the proper idiom
        in the main module:

            if __name__ == '__main__':
                freeze_support()
                ...

        The "freeze_support()" line can be omitted if the program
        is not going to be frozen to produce an executable.
2023-04-13 17:46:14,424 - distributed.nanny - ERROR - Failed to start process
Traceback (most recent call last):
  File "/g/data3/hh5/public/apps/miniconda3/envs/analysis3-23.01/lib/python3.9/site-packages/distributed/nanny.py", line 442, in instantiate
    result = await self.process.start()
  File "/g/data3/hh5/public/apps/miniconda3/envs/analysis3-23.01/lib/python3.9/site-packages/distributed/nanny.py", line 711, in start
    await self.process.start()
  File "/g/data3/hh5/public/apps/miniconda3/envs/analysis3-23.01/lib/python3.9/site-packages/distributed/process.py", line 55, in _call_and_set_future
    res = func(*args, **kwargs)
  File "/g/data3/hh5/public/apps/miniconda3/envs/analysis3-23.01/lib/python3.9/site-packages/distributed/process.py", line 215, in _start
    process.start()
  File "/g/data3/hh5/public/apps/miniconda3/envs/analysis3-23.01/lib/python3.9/multiprocessing/process.py", line 121, in start
    self._popen = self._Popen(self)
  File "/g/data3/hh5/public/apps/miniconda3/envs/analysis3-23.01/lib/python3.9/multiprocessing/context.py", line 284, in _Popen
    return Popen(process_obj)
  File "/g/data3/hh5/public/apps/miniconda3/envs/analysis3-23.01/lib/python3.9/multiprocessing/popen_spawn_posix.py", line 32, in __init__
    super().__init__(process_obj)
  File "/g/data3/hh5/public/apps/miniconda3/envs/analysis3-23.01/lib/python3.9/multiprocessing/popen_fork.py", line 19, in __init__
    self._launch(process_obj)
  File "/g/data3/hh5/public/apps/miniconda3/envs/analysis3-23.01/lib/python3.9/multiprocessing/popen_spawn_posix.py", line 42, in _launch
    prep_data = spawn.get_preparation_data(process_obj._name)
  File "/g/data3/hh5/public/apps/miniconda3/envs/analysis3-23.01/lib/python3.9/multiprocessing/spawn.py", line 154, in get_preparation_data
    _check_not_importing_main()
  File "/g/data3/hh5/public/apps/miniconda3/envs/analysis3-23.01/lib/python3.9/multiprocessing/spawn.py", line 134, in _check_not_importing_main
    raise RuntimeError('''
RuntimeError: 
        An attempt has been made to start a new process before the
        current process has finished its bootstrapping phase.

        This probably means that you are not using fork to start your
        child processes and you have forgotten to use the proper idiom
        in the main module:

            if __name__ == '__main__':
                freeze_support()
                ...

        The "freeze_support()" line can be omitted if the program
        is not going to be frozen to produce an executable.
2023-04-13 17:46:14,425 - distributed.nanny - ERROR - Failed to start process
Traceback (most recent call last):
  File "/g/data3/hh5/public/apps/miniconda3/envs/analysis3-23.01/lib/python3.9/site-packages/distributed/nanny.py", line 442, in instantiate
    result = await self.process.start()
  File "/g/data3/hh5/public/apps/miniconda3/envs/analysis3-23.01/lib/python3.9/site-packages/distributed/nanny.py", line 711, in start
    await self.process.start()
  File "/g/data3/hh5/public/apps/miniconda3/envs/analysis3-23.01/lib/python3.9/site-packages/distributed/process.py", line 55, in _call_and_set_future
    res = func(*args, **kwargs)
  File "/g/data3/hh5/public/apps/miniconda3/envs/analysis3-23.01/lib/python3.9/site-packages/distributed/process.py", line 215, in _start
    process.start()
  File "/g/data3/hh5/public/apps/miniconda3/envs/analysis3-23.01/lib/python3.9/multiprocessing/process.py", line 121, in start
    self._popen = self._Popen(self)
  File "/g/data3/hh5/public/apps/miniconda3/envs/analysis3-23.01/lib/python3.9/multiprocessing/context.py", line 284, in _Popen
    return Popen(process_obj)
  File "/g/data3/hh5/public/apps/miniconda3/envs/analysis3-23.01/lib/python3.9/multiprocessing/popen_spawn_posix.py", line 32, in __init__
    super().__init__(process_obj)
  File "/g/data3/hh5/public/apps/miniconda3/envs/analysis3-23.01/lib/python3.9/multiprocessing/popen_fork.py", line 19, in __init__
    self._launch(process_obj)
  File "/g/data3/hh5/public/apps/miniconda3/envs/analysis3-23.01/lib/python3.9/multiprocessing/popen_spawn_posix.py", line 42, in _launch
    prep_data = spawn.get_preparation_data(process_obj._name)
  File "/g/data3/hh5/public/apps/miniconda3/envs/analysis3-23.01/lib/python3.9/multiprocessing/spawn.py", line 154, in get_preparation_data
    _check_not_importing_main()
  File "/g/data3/hh5/public/apps/miniconda3/envs/analysis3-23.01/lib/python3.9/multiprocessing/spawn.py", line 134, in _check_not_importing_main
    raise RuntimeError('''
RuntimeError: 
        An attempt has been made to start a new process before the
        current process has finished its bootstrapping phase.

        This probably means that you are not using fork to start your
        child processes and you have forgotten to use the proper idiom
        in the main module:

            if __name__ == '__main__':
                freeze_support()
                ...

        The "freeze_support()" line can be omitted if the program
        is not going to be frozen to produce an executable.
2023-04-13 17:46:14,425 - distributed.nanny - ERROR - Failed to start process
Traceback (most recent call last):
  File "/g/data3/hh5/public/apps/miniconda3/envs/analysis3-23.01/lib/python3.9/site-packages/distributed/nanny.py", line 442, in instantiate
    result = await self.process.start()
  File "/g/data3/hh5/public/apps/miniconda3/envs/analysis3-23.01/lib/python3.9/site-packages/distributed/nanny.py", line 711, in start
    await self.process.start()
  File "/g/data3/hh5/public/apps/miniconda3/envs/analysis3-23.01/lib/python3.9/site-packages/distributed/process.py", line 55, in _call_and_set_future
    res = func(*args, **kwargs)
  File "/g/data3/hh5/public/apps/miniconda3/envs/analysis3-23.01/lib/python3.9/site-packages/distributed/process.py", line 215, in _start
    process.start()
  File "/g/data3/hh5/public/apps/miniconda3/envs/analysis3-23.01/lib/python3.9/multiprocessing/process.py", line 121, in start
    self._popen = self._Popen(self)
  File "/g/data3/hh5/public/apps/miniconda3/envs/analysis3-23.01/lib/python3.9/multiprocessing/context.py", line 284, in _Popen
    return Popen(process_obj)
  File "/g/data3/hh5/public/apps/miniconda3/envs/analysis3-23.01/lib/python3.9/multiprocessing/popen_spawn_posix.py", line 32, in __init__
    super().__init__(process_obj)
  File "/g/data3/hh5/public/apps/miniconda3/envs/analysis3-23.01/lib/python3.9/multiprocessing/popen_fork.py", line 19, in __init__
    self._launch(process_obj)
  File "/g/data3/hh5/public/apps/miniconda3/envs/analysis3-23.01/lib/python3.9/multiprocessing/popen_spawn_posix.py", line 42, in _launch
    prep_data = spawn.get_preparation_data(process_obj._name)
  File "/g/data3/hh5/public/apps/miniconda3/envs/analysis3-23.01/lib/python3.9/multiprocessing/spawn.py", line 154, in get_preparation_data
    _check_not_importing_main()
  File "/g/data3/hh5/public/apps/miniconda3/envs/analysis3-23.01/lib/python3.9/multiprocessing/spawn.py", line 134, in _check_not_importing_main
    raise RuntimeError('''
RuntimeError: 
        An attempt has been made to start a new process before the
        current process has finished its bootstrapping phase.

        This probably means that you are not using fork to start your
        child processes and you have forgotten to use the proper idiom
        in the main module:

            if __name__ == '__main__':
                freeze_support()
                ...

        The "freeze_support()" line can be omitted if the program
        is not going to be frozen to produce an executable.
2023-04-13 17:46:14,426 - distributed.nanny - ERROR - Failed to start process
Traceback (most recent call last):
  File "/g/data3/hh5/public/apps/miniconda3/envs/analysis3-23.01/lib/python3.9/site-packages/distributed/nanny.py", line 442, in instantiate
    result = await self.process.start()
  File "/g/data3/hh5/public/apps/miniconda3/envs/analysis3-23.01/lib/python3.9/site-packages/distributed/nanny.py", line 711, in start
    await self.process.start()
  File "/g/data3/hh5/public/apps/miniconda3/envs/analysis3-23.01/lib/python3.9/site-packages/distributed/process.py", line 55, in _call_and_set_future
    res = func(*args, **kwargs)
  File "/g/data3/hh5/public/apps/miniconda3/envs/analysis3-23.01/lib/python3.9/site-packages/distributed/process.py", line 215, in _start
    process.start()
  File "/g/data3/hh5/public/apps/miniconda3/envs/analysis3-23.01/lib/python3.9/multiprocessing/process.py", line 121, in start
    self._popen = self._Popen(self)
  File "/g/data3/hh5/public/apps/miniconda3/envs/analysis3-23.01/lib/python3.9/multiprocessing/context.py", line 284, in _Popen
    return Popen(process_obj)
  File "/g/data3/hh5/public/apps/miniconda3/envs/analysis3-23.01/lib/python3.9/multiprocessing/popen_spawn_posix.py", line 32, in __init__
    super().__init__(process_obj)
  File "/g/data3/hh5/public/apps/miniconda3/envs/analysis3-23.01/lib/python3.9/multiprocessing/popen_fork.py", line 19, in __init__
    self._launch(process_obj)
  File "/g/data3/hh5/public/apps/miniconda3/envs/analysis3-23.01/lib/python3.9/multiprocessing/popen_spawn_posix.py", line 42, in _launch
    prep_data = spawn.get_preparation_data(process_obj._name)
  File "/g/data3/hh5/public/apps/miniconda3/envs/analysis3-23.01/lib/python3.9/multiprocessing/spawn.py", line 154, in get_preparation_data
    _check_not_importing_main()
  File "/g/data3/hh5/public/apps/miniconda3/envs/analysis3-23.01/lib/python3.9/multiprocessing/spawn.py", line 134, in _check_not_importing_main
    raise RuntimeError('''
RuntimeError: 
        An attempt has been made to start a new process before the
        current process has finished its bootstrapping phase.

        This probably means that you are not using fork to start your
        child processes and you have forgotten to use the proper idiom
        in the main module:

            if __name__ == '__main__':
                freeze_support()
                ...

        The "freeze_support()" line can be omitted if the program
        is not going to be frozen to produce an executable.
2023-04-13 17:46:14,427 - distributed.nanny - ERROR - Failed to start process
Traceback (most recent call last):
  File "/g/data3/hh5/public/apps/miniconda3/envs/analysis3-23.01/lib/python3.9/site-packages/distributed/nanny.py", line 442, in instantiate
    result = await self.process.start()
  File "/g/data3/hh5/public/apps/miniconda3/envs/analysis3-23.01/lib/python3.9/site-packages/distributed/nanny.py", line 711, in start
    await self.process.start()
  File "/g/data3/hh5/public/apps/miniconda3/envs/analysis3-23.01/lib/python3.9/site-packages/distributed/process.py", line 55, in _call_and_set_future
    res = func(*args, **kwargs)
  File "/g/data3/hh5/public/apps/miniconda3/envs/analysis3-23.01/lib/python3.9/site-packages/distributed/process.py", line 215, in _start
    process.start()
  File "/g/data3/hh5/public/apps/miniconda3/envs/analysis3-23.01/lib/python3.9/multiprocessing/process.py", line 121, in start
    self._popen = self._Popen(self)
  File "/g/data3/hh5/public/apps/miniconda3/envs/analysis3-23.01/lib/python3.9/multiprocessing/context.py", line 284, in _Popen
    return Popen(process_obj)
  File "/g/data3/hh5/public/apps/miniconda3/envs/analysis3-23.01/lib/python3.9/multiprocessing/popen_spawn_posix.py", line 32, in __init__
    super().__init__(process_obj)
  File "/g/data3/hh5/public/apps/miniconda3/envs/analysis3-23.01/lib/python3.9/multiprocessing/popen_fork.py", line 19, in __init__
    self._launch(process_obj)
  File "/g/data3/hh5/public/apps/miniconda3/envs/analysis3-23.01/lib/python3.9/multiprocessing/popen_spawn_posix.py", line 42, in _launch
    prep_data = spawn.get_preparation_data(process_obj._name)
  File "/g/data3/hh5/public/apps/miniconda3/envs/analysis3-23.01/lib/python3.9/multiprocessing/spawn.py", line 154, in get_preparation_data
    _check_not_importing_main()
  File "/g/data3/hh5/public/apps/miniconda3/envs/analysis3-23.01/lib/python3.9/multiprocessing/spawn.py", line 134, in _check_not_importing_main
    raise RuntimeError('''
RuntimeError: 
        An attempt has been made to start a new process before the
        current process has finished its bootstrapping phase.

        This probably means that you are not using fork to start your
        child processes and you have forgotten to use the proper idiom
        in the main module:

            if __name__ == '__main__':
                freeze_support()
                ...

        The "freeze_support()" line can be omitted if the program
        is not going to be frozen to produce an executable.
2023-04-13 17:46:14,441 - distributed.nanny - ERROR - Failed to start process
Traceback (most recent call last):
  File "/g/data3/hh5/public/apps/miniconda3/envs/analysis3-23.01/lib/python3.9/site-packages/distributed/nanny.py", line 442, in instantiate
    result = await self.process.start()
  File "/g/data3/hh5/public/apps/miniconda3/envs/analysis3-23.01/lib/python3.9/site-packages/distributed/nanny.py", line 711, in start
    await self.process.start()
  File "/g/data3/hh5/public/apps/miniconda3/envs/analysis3-23.01/lib/python3.9/site-packages/distributed/process.py", line 55, in _call_and_set_future
    res = func(*args, **kwargs)
  File "/g/data3/hh5/public/apps/miniconda3/envs/analysis3-23.01/lib/python3.9/site-packages/distributed/process.py", line 215, in _start
    process.start()
  File "/g/data3/hh5/public/apps/miniconda3/envs/analysis3-23.01/lib/python3.9/multiprocessing/process.py", line 121, in start
    self._popen = self._Popen(self)
  File "/g/data3/hh5/public/apps/miniconda3/envs/analysis3-23.01/lib/python3.9/multiprocessing/context.py", line 284, in _Popen
    return Popen(process_obj)
  File "/g/data3/hh5/public/apps/miniconda3/envs/analysis3-23.01/lib/python3.9/multiprocessing/popen_spawn_posix.py", line 32, in __init__
    super().__init__(process_obj)
  File "/g/data3/hh5/public/apps/miniconda3/envs/analysis3-23.01/lib/python3.9/multiprocessing/popen_fork.py", line 19, in __init__
    self._launch(process_obj)
  File "/g/data3/hh5/public/apps/miniconda3/envs/analysis3-23.01/lib/python3.9/multiprocessing/popen_spawn_posix.py", line 42, in _launch
    prep_data = spawn.get_preparation_data(process_obj._name)
  File "/g/data3/hh5/public/apps/miniconda3/envs/analysis3-23.01/lib/python3.9/multiprocessing/spawn.py", line 154, in get_preparation_data
    _check_not_importing_main()
  File "/g/data3/hh5/public/apps/miniconda3/envs/analysis3-23.01/lib/python3.9/multiprocessing/spawn.py", line 134, in _check_not_importing_main
    raise RuntimeError('''
RuntimeError: 
        An attempt has been made to start a new process before the
        current process has finished its bootstrapping phase.

        This probably means that you are not using fork to start your
        child processes and you have forgotten to use the proper idiom
        in the main module:

            if __name__ == '__main__':
                freeze_support()
                ...

        The "freeze_support()" line can be omitted if the program
        is not going to be frozen to produce an executable.
2023-04-13 17:46:14,445 - distributed.nanny - ERROR - Failed to start process
Traceback (most recent call last):
  File "/g/data3/hh5/public/apps/miniconda3/envs/analysis3-23.01/lib/python3.9/site-packages/distributed/nanny.py", line 442, in instantiate
    result = await self.process.start()
  File "/g/data3/hh5/public/apps/miniconda3/envs/analysis3-23.01/lib/python3.9/site-packages/distributed/nanny.py", line 711, in start
    await self.process.start()
  File "/g/data3/hh5/public/apps/miniconda3/envs/analysis3-23.01/lib/python3.9/site-packages/distributed/process.py", line 55, in _call_and_set_future
    res = func(*args, **kwargs)
  File "/g/data3/hh5/public/apps/miniconda3/envs/analysis3-23.01/lib/python3.9/site-packages/distributed/process.py", line 215, in _start
    process.start()
  File "/g/data3/hh5/public/apps/miniconda3/envs/analysis3-23.01/lib/python3.9/multiprocessing/process.py", line 121, in start
    self._popen = self._Popen(self)
  File "/g/data3/hh5/public/apps/miniconda3/envs/analysis3-23.01/lib/python3.9/multiprocessing/context.py", line 284, in _Popen
    return Popen(process_obj)
  File "/g/data3/hh5/public/apps/miniconda3/envs/analysis3-23.01/lib/python3.9/multiprocessing/popen_spawn_posix.py", line 32, in __init__
    super().__init__(process_obj)
  File "/g/data3/hh5/public/apps/miniconda3/envs/analysis3-23.01/lib/python3.9/multiprocessing/popen_fork.py", line 19, in __init__
    self._launch(process_obj)
  File "/g/data3/hh5/public/apps/miniconda3/envs/analysis3-23.01/lib/python3.9/multiprocessing/popen_spawn_posix.py", line 42, in _launch
    prep_data = spawn.get_preparation_data(process_obj._name)
  File "/g/data3/hh5/public/apps/miniconda3/envs/analysis3-23.01/lib/python3.9/multiprocessing/spawn.py", line 154, in get_preparation_data
    _check_not_importing_main()
  File "/g/data3/hh5/public/apps/miniconda3/envs/analysis3-23.01/lib/python3.9/multiprocessing/spawn.py", line 134, in _check_not_importing_main
    raise RuntimeError('''
RuntimeError: 
        An attempt has been made to start a new process before the
        current process has finished its bootstrapping phase.

        This probably means that you are not using fork to start your
        child processes and you have forgotten to use the proper idiom
        in the main module:

            if __name__ == '__main__':
                freeze_support()
                ...

        The "freeze_support()" line can be omitted if the program
        is not going to be frozen to produce an executable.
2023-04-13 17:46:14,445 - distributed.nanny - ERROR - Failed to start process
Traceback (most recent call last):
  File "/g/data3/hh5/public/apps/miniconda3/envs/analysis3-23.01/lib/python3.9/site-packages/distributed/nanny.py", line 442, in instantiate
    result = await self.process.start()
  File "/g/data3/hh5/public/apps/miniconda3/envs/analysis3-23.01/lib/python3.9/site-packages/distributed/nanny.py", line 711, in start
    await self.process.start()
  File "/g/data3/hh5/public/apps/miniconda3/envs/analysis3-23.01/lib/python3.9/site-packages/distributed/process.py", line 55, in _call_and_set_future
    res = func(*args, **kwargs)
  File "/g/data3/hh5/public/apps/miniconda3/envs/analysis3-23.01/lib/python3.9/site-packages/distributed/process.py", line 215, in _start
    process.start()
  File "/g/data3/hh5/public/apps/miniconda3/envs/analysis3-23.01/lib/python3.9/multiprocessing/process.py", line 121, in start
    self._popen = self._Popen(self)
  File "/g/data3/hh5/public/apps/miniconda3/envs/analysis3-23.01/lib/python3.9/multiprocessing/context.py", line 284, in _Popen
    return Popen(process_obj)
  File "/g/data3/hh5/public/apps/miniconda3/envs/analysis3-23.01/lib/python3.9/multiprocessing/popen_spawn_posix.py", line 32, in __init__
    super().__init__(process_obj)
  File "/g/data3/hh5/public/apps/miniconda3/envs/analysis3-23.01/lib/python3.9/multiprocessing/popen_fork.py", line 19, in __init__
    self._launch(process_obj)
  File "/g/data3/hh5/public/apps/miniconda3/envs/analysis3-23.01/lib/python3.9/multiprocessing/popen_spawn_posix.py", line 42, in _launch
    prep_data = spawn.get_preparation_data(process_obj._name)
  File "/g/data3/hh5/public/apps/miniconda3/envs/analysis3-23.01/lib/python3.9/multiprocessing/spawn.py", line 154, in get_preparation_data
    _check_not_importing_main()
  File "/g/data3/hh5/public/apps/miniconda3/envs/analysis3-23.01/lib/python3.9/multiprocessing/spawn.py", line 134, in _check_not_importing_main
    raise RuntimeError('''
RuntimeError: 
        An attempt has been made to start a new process before the
        current process has finished its bootstrapping phase.

        This probably means that you are not using fork to start your
        child processes and you have forgotten to use the proper idiom
        in the main module:

            if __name__ == '__main__':
                freeze_support()
                ...

        The "freeze_support()" line can be omitted if the program
        is not going to be frozen to produce an executable.
2023-04-13 17:46:14,445 - distributed.nanny - ERROR - Failed to start process
Traceback (most recent call last):
  File "/g/data3/hh5/public/apps/miniconda3/envs/analysis3-23.01/lib/python3.9/site-packages/distributed/nanny.py", line 442, in instantiate
    result = await self.process.start()
  File "/g/data3/hh5/public/apps/miniconda3/envs/analysis3-23.01/lib/python3.9/site-packages/distributed/nanny.py", line 711, in start
    await self.process.start()
  File "/g/data3/hh5/public/apps/miniconda3/envs/analysis3-23.01/lib/python3.9/site-packages/distributed/process.py", line 55, in _call_and_set_future
    res = func(*args, **kwargs)
  File "/g/data3/hh5/public/apps/miniconda3/envs/analysis3-23.01/lib/python3.9/site-packages/distributed/process.py", line 215, in _start
    process.start()
  File "/g/data3/hh5/public/apps/miniconda3/envs/analysis3-23.01/lib/python3.9/multiprocessing/process.py", line 121, in start
    self._popen = self._Popen(self)
  File "/g/data3/hh5/public/apps/miniconda3/envs/analysis3-23.01/lib/python3.9/multiprocessing/context.py", line 284, in _Popen
    return Popen(process_obj)
  File "/g/data3/hh5/public/apps/miniconda3/envs/analysis3-23.01/lib/python3.9/multiprocessing/popen_spawn_posix.py", line 32, in __init__
    super().__init__(process_obj)
  File "/g/data3/hh5/public/apps/miniconda3/envs/analysis3-23.01/lib/python3.9/multiprocessing/popen_fork.py", line 19, in __init__
    self._launch(process_obj)
  File "/g/data3/hh5/public/apps/miniconda3/envs/analysis3-23.01/lib/python3.9/multiprocessing/popen_spawn_posix.py", line 42, in _launch
    prep_data = spawn.get_preparation_data(process_obj._name)
  File "/g/data3/hh5/public/apps/miniconda3/envs/analysis3-23.01/lib/python3.9/multiprocessing/spawn.py", line 154, in get_preparation_data
    _check_not_importing_main()
  File "/g/data3/hh5/public/apps/miniconda3/envs/analysis3-23.01/lib/python3.9/multiprocessing/spawn.py", line 134, in _check_not_importing_main
    raise RuntimeError('''
RuntimeError: 
        An attempt has been made to start a new process before the
        current process has finished its bootstrapping phase.

        This probably means that you are not using fork to start your
        child processes and you have forgotten to use the proper idiom
        in the main module:

            if __name__ == '__main__':
                freeze_support()
                ...

        The "freeze_support()" line can be omitted if the program
        is not going to be frozen to produce an executable.
2023-04-13 17:46:14,446 - distributed.nanny - ERROR - Failed to start process
Traceback (most recent call last):
  File "/g/data3/hh5/public/apps/miniconda3/envs/analysis3-23.01/lib/python3.9/site-packages/distributed/nanny.py", line 442, in instantiate
    result = await self.process.start()
  File "/g/data3/hh5/public/apps/miniconda3/envs/analysis3-23.01/lib/python3.9/site-packages/distributed/nanny.py", line 711, in start
    await self.process.start()
  File "/g/data3/hh5/public/apps/miniconda3/envs/analysis3-23.01/lib/python3.9/site-packages/distributed/process.py", line 55, in _call_and_set_future
    res = func(*args, **kwargs)
  File "/g/data3/hh5/public/apps/miniconda3/envs/analysis3-23.01/lib/python3.9/site-packages/distributed/process.py", line 215, in _start
    process.start()
  File "/g/data3/hh5/public/apps/miniconda3/envs/analysis3-23.01/lib/python3.9/multiprocessing/process.py", line 121, in start
    self._popen = self._Popen(self)
  File "/g/data3/hh5/public/apps/miniconda3/envs/analysis3-23.01/lib/python3.9/multiprocessing/context.py", line 284, in _Popen
    return Popen(process_obj)
  File "/g/data3/hh5/public/apps/miniconda3/envs/analysis3-23.01/lib/python3.9/multiprocessing/popen_spawn_posix.py", line 32, in __init__
    super().__init__(process_obj)
  File "/g/data3/hh5/public/apps/miniconda3/envs/analysis3-23.01/lib/python3.9/multiprocessing/popen_fork.py", line 19, in __init__
    self._launch(process_obj)
  File "/g/data3/hh5/public/apps/miniconda3/envs/analysis3-23.01/lib/python3.9/multiprocessing/popen_spawn_posix.py", line 42, in _launch
    prep_data = spawn.get_preparation_data(process_obj._name)
  File "/g/data3/hh5/public/apps/miniconda3/envs/analysis3-23.01/lib/python3.9/multiprocessing/spawn.py", line 154, in get_preparation_data
    _check_not_importing_main()
  File "/g/data3/hh5/public/apps/miniconda3/envs/analysis3-23.01/lib/python3.9/multiprocessing/spawn.py", line 134, in _check_not_importing_main
    raise RuntimeError('''
RuntimeError: 
        An attempt has been made to start a new process before the
        current process has finished its bootstrapping phase.

        This probably means that you are not using fork to start your
        child processes and you have forgotten to use the proper idiom
        in the main module:

            if __name__ == '__main__':
                freeze_support()
                ...

        The "freeze_support()" line can be omitted if the program
        is not going to be frozen to produce an executable.
2023-04-13 17:46:14,446 - distributed.nanny - ERROR - Failed to start process
Traceback (most recent call last):
  File "/g/data3/hh5/public/apps/miniconda3/envs/analysis3-23.01/lib/python3.9/site-packages/distributed/nanny.py", line 442, in instantiate
    result = await self.process.start()
  File "/g/data3/hh5/public/apps/miniconda3/envs/analysis3-23.01/lib/python3.9/site-packages/distributed/nanny.py", line 711, in start
    await self.process.start()
  File "/g/data3/hh5/public/apps/miniconda3/envs/analysis3-23.01/lib/python3.9/site-packages/distributed/process.py", line 55, in _call_and_set_future
    res = func(*args, **kwargs)
  File "/g/data3/hh5/public/apps/miniconda3/envs/analysis3-23.01/lib/python3.9/site-packages/distributed/process.py", line 215, in _start
    process.start()
  File "/g/data3/hh5/public/apps/miniconda3/envs/analysis3-23.01/lib/python3.9/multiprocessing/process.py", line 121, in start
    self._popen = self._Popen(self)
  File "/g/data3/hh5/public/apps/miniconda3/envs/analysis3-23.01/lib/python3.9/multiprocessing/context.py", line 284, in _Popen
    return Popen(process_obj)
  File "/g/data3/hh5/public/apps/miniconda3/envs/analysis3-23.01/lib/python3.9/multiprocessing/popen_spawn_posix.py", line 32, in __init__
    super().__init__(process_obj)
  File "/g/data3/hh5/public/apps/miniconda3/envs/analysis3-23.01/lib/python3.9/multiprocessing/popen_fork.py", line 19, in __init__
    self._launch(process_obj)
  File "/g/data3/hh5/public/apps/miniconda3/envs/analysis3-23.01/lib/python3.9/multiprocessing/popen_spawn_posix.py", line 42, in _launch
    prep_data = spawn.get_preparation_data(process_obj._name)
  File "/g/data3/hh5/public/apps/miniconda3/envs/analysis3-23.01/lib/python3.9/multiprocessing/spawn.py", line 154, in get_preparation_data
    _check_not_importing_main()
  File "/g/data3/hh5/public/apps/miniconda3/envs/analysis3-23.01/lib/python3.9/multiprocessing/spawn.py", line 134, in _check_not_importing_main
    raise RuntimeError('''
RuntimeError: 
        An attempt has been made to start a new process before the
        current process has finished its bootstrapping phase.

        This probably means that you are not using fork to start your
        child processes and you have forgotten to use the proper idiom
        in the main module:

            if __name__ == '__main__':
                freeze_support()
                ...

        The "freeze_support()" line can be omitted if the program
        is not going to be frozen to produce an executable.
2023-04-13 17:46:14,446 - distributed.nanny - ERROR - Failed to start process
Traceback (most recent call last):
  File "/g/data3/hh5/public/apps/miniconda3/envs/analysis3-23.01/lib/python3.9/site-packages/distributed/nanny.py", line 442, in instantiate
    result = await self.process.start()
  File "/g/data3/hh5/public/apps/miniconda3/envs/analysis3-23.01/lib/python3.9/site-packages/distributed/nanny.py", line 711, in start
    await self.process.start()
  File "/g/data3/hh5/public/apps/miniconda3/envs/analysis3-23.01/lib/python3.9/site-packages/distributed/process.py", line 55, in _call_and_set_future
    res = func(*args, **kwargs)
  File "/g/data3/hh5/public/apps/miniconda3/envs/analysis3-23.01/lib/python3.9/site-packages/distributed/process.py", line 215, in _start
    process.start()
  File "/g/data3/hh5/public/apps/miniconda3/envs/analysis3-23.01/lib/python3.9/multiprocessing/process.py", line 121, in start
    self._popen = self._Popen(self)
  File "/g/data3/hh5/public/apps/miniconda3/envs/analysis3-23.01/lib/python3.9/multiprocessing/context.py", line 284, in _Popen
    return Popen(process_obj)
  File "/g/data3/hh5/public/apps/miniconda3/envs/analysis3-23.01/lib/python3.9/multiprocessing/popen_spawn_posix.py", line 32, in __init__
    super().__init__(process_obj)
  File "/g/data3/hh5/public/apps/miniconda3/envs/analysis3-23.01/lib/python3.9/multiprocessing/popen_fork.py", line 19, in __init__
    self._launch(process_obj)
  File "/g/data3/hh5/public/apps/miniconda3/envs/analysis3-23.01/lib/python3.9/multiprocessing/popen_spawn_posix.py", line 42, in _launch
    prep_data = spawn.get_preparation_data(process_obj._name)
  File "/g/data3/hh5/public/apps/miniconda3/envs/analysis3-23.01/lib/python3.9/multiprocessing/spawn.py", line 154, in get_preparation_data
    _check_not_importing_main()
  File "/g/data3/hh5/public/apps/miniconda3/envs/analysis3-23.01/lib/python3.9/multiprocessing/spawn.py", line 134, in _check_not_importing_main
    raise RuntimeError('''
RuntimeError: 
        An attempt has been made to start a new process before the
        current process has finished its bootstrapping phase.

        This probably means that you are not using fork to start your
        child processes and you have forgotten to use the proper idiom
        in the main module:

            if __name__ == '__main__':
                freeze_support()
                ...

        The "freeze_support()" line can be omitted if the program
        is not going to be frozen to produce an executable.
2023-04-13 17:46:14,447 - distributed.nanny - ERROR - Failed to start process
Traceback (most recent call last):
  File "/g/data3/hh5/public/apps/miniconda3/envs/analysis3-23.01/lib/python3.9/site-packages/distributed/nanny.py", line 442, in instantiate
    result = await self.process.start()
  File "/g/data3/hh5/public/apps/miniconda3/envs/analysis3-23.01/lib/python3.9/site-packages/distributed/nanny.py", line 711, in start
    await self.process.start()
  File "/g/data3/hh5/public/apps/miniconda3/envs/analysis3-23.01/lib/python3.9/site-packages/distributed/process.py", line 55, in _call_and_set_future
    res = func(*args, **kwargs)
  File "/g/data3/hh5/public/apps/miniconda3/envs/analysis3-23.01/lib/python3.9/site-packages/distributed/process.py", line 215, in _start
    process.start()
  File "/g/data3/hh5/public/apps/miniconda3/envs/analysis3-23.01/lib/python3.9/multiprocessing/process.py", line 121, in start
    self._popen = self._Popen(self)
  File "/g/data3/hh5/public/apps/miniconda3/envs/analysis3-23.01/lib/python3.9/multiprocessing/context.py", line 284, in _Popen
    return Popen(process_obj)
  File "/g/data3/hh5/public/apps/miniconda3/envs/analysis3-23.01/lib/python3.9/multiprocessing/popen_spawn_posix.py", line 32, in __init__
    super().__init__(process_obj)
  File "/g/data3/hh5/public/apps/miniconda3/envs/analysis3-23.01/lib/python3.9/multiprocessing/popen_fork.py", line 19, in __init__
    self._launch(process_obj)
  File "/g/data3/hh5/public/apps/miniconda3/envs/analysis3-23.01/lib/python3.9/multiprocessing/popen_spawn_posix.py", line 42, in _launch
    prep_data = spawn.get_preparation_data(process_obj._name)
  File "/g/data3/hh5/public/apps/miniconda3/envs/analysis3-23.01/lib/python3.9/multiprocessing/spawn.py", line 154, in get_preparation_data
    _check_not_importing_main()
  File "/g/data3/hh5/public/apps/miniconda3/envs/analysis3-23.01/lib/python3.9/multiprocessing/spawn.py", line 134, in _check_not_importing_main
    raise RuntimeError('''
RuntimeError: 
        An attempt has been made to start a new process before the
        current process has finished its bootstrapping phase.

        This probably means that you are not using fork to start your
        child processes and you have forgotten to use the proper idiom
        in the main module:

            if __name__ == '__main__':
                freeze_support()
                ...

        The "freeze_support()" line can be omitted if the program
        is not going to be frozen to produce an executable.
=>> PBS: job killed: walltime 86517 exceeded limit 86400
/g/data3/hh5/public/apps/miniconda3/envs/analysis3-23.01/lib/python3.9/multiprocessing/resource_tracker.py:216: UserWarning: resource_tracker: There appear to be 432 leaked semaphore objects to clean up at shutdown
  warnings.warn('resource_tracker: There appear to be %d '
